<?xml version="1.0"?>
<robot name="C:/Users/bellu/Documents/webots/echoarm/controllers/echoarm.urdf" xmlns:xacro="http://ros.org/wiki/xacro">
  <link name="base_link">
  </link>
  <joint name="slider_piston_base" type="prismatic">
    <parent link="base_link"/>
    <child link="solid"/>
    <axis xyz="1 0 0"/>
    <origin xyz="0 0 0" rpy="0 0 0"/>
    <limit effort="10" lower="-0.8" upper="0.8" velocity="5"/>
  </joint>
  <link name="solid">
  </link>
  <link name="appearance">
  </link>
  <link name="base_and_box">
  </link>
  <joint name="piston_motor" type="prismatic">
    <parent link="base_and_box"/>
    <child link="LINK_PISTON"/>
    <axis xyz="0 1 0"/>
    <origin xyz="0 0.04 0" rpy="0 0 0"/>
    <limit effort="10" velocity="10"/>
  </joint>
  <link name="LINK_PISTON">
  </link>
  <joint name="elbow_motor" type="continuous">
    <parent link="LINK_PISTON"/>
    <child link="solid_0"/>
    <axis xyz="0 1 0"/>
    <limit effort="10" velocity="10"/>
    <origin xyz="0 0.17 0" rpy="0 0 0"/>
  </joint>
  <link name="solid_0">
  </link>
  <joint name="lower_arm_rotation_motor" type="continuous">
    <parent link="solid_0"/>
    <child link="solid_1"/>
    <axis xyz="0 1 -0.000004"/>
    <limit effort="10" velocity="10"/>
    <origin xyz="0 0.075 0.0736" rpy="1.5708 0 0"/>
  </joint>
  <link name="solid_1">
  </link>
  <joint name="lower_arm_vertical_motor" type="continuous">
    <parent link="solid_1"/>
    <child link="solid_2"/>
    <axis xyz="0.000003 -1 0.000003"/>
    <limit effort="10" velocity="10"/>
    <origin xyz="0 0.06 0" rpy="-0.785397 1.570792 0.785397"/>
  </joint>
  <link name="solid_2">
  </link>
  <link name="solid_3">
  </link>
  <link name="receiver">
  </link>
</robot>
