#VRML_SIM R2025a utf8

EXTERNPROTO "https://raw.githubusercontent.com/cyberbotics/webots/R2025a/projects/objects/backgrounds/protos/TexturedBackground.proto"
EXTERNPROTO "https://raw.githubusercontent.com/cyberbotics/webots/R2025a/projects/objects/backgrounds/protos/TexturedBackgroundLight.proto"
EXTERNPROTO "https://raw.githubusercontent.com/cyberbotics/webots/R2025a/projects/objects/floors/protos/RectangleArena.proto"

WorldInfo {
}
Viewpoint {
  orientation 0.04735006900739271 -0.8140357184332536 0.5788815250807816 5.947258981413083
  position -3.728827243773324 0.7783462397296587 1.2985483394693131
}
TexturedBackground {
}
TexturedBackgroundLight {
}
RectangleArena {
  floorSize 1.5 1.5
  floorTileSize 1 1
}
Robot {
  translation -7.391538271298344e-21 -6.447803873638253e-21 0.00015391923197353397
  rotation -0.970727174780174 0.2401746579750109 0.002210386818682905 6.415086376633721e-18
  children [
    Solid {
      children [
        Solid {
          translation 0 0 0.395
          children [
            SliderJoint {
              jointParameters JointParameters {
                position 0.049280000000000004
                minStop 0.12
                maxStop 0.12
              }
              device [
                PositionSensor {
                  name "slider_piston_base_sensor"
                }
                LinearMotor {
                  name "slider_piston_base"
                  maxForce 30
                }
              ]
              endPoint Solid {
                translation 0 0 0.07928
                children [
                  HingeJoint {
                    jointParameters HingeJointParameters {
                      position 0.5017600000000006
                      axis 0 0 1
                      anchor 0 0 0.26
                    }
                    device [
                      PositionSensor {
                        name "piston_elbow_sensor"
                      }
                      RotationalMotor {
                        name "piston_elbow_motor"
                      }
                    ]
                    endPoint Solid {
                      translation 0 0 0.26
                      rotation 0 0 1 0.5017600000000004
                      children [
                        HingeJoint {
                          jointParameters HingeJointParameters {
                            anchor 0.265 0 0.38
                          }
                          device [
                            PositionSensor {
                              name "elbow_sensor"
                            }
                            RotationalMotor {
                              name "elbow_motor"
                            }
                          ]
                          endPoint Solid {
                            translation 0.265 0 0.38
                            rotation 0 1 0 1.5708003061004252
                            children [
                              HingeJoint {
                                jointParameters HingeJointParameters {
                                  axis 0 1 0
                                  anchor 0 0 0.425
                                }
                                device [
                                  PositionSensor {
                                    name "lower_arm_sensor"
                                  }
                                  RotationalMotor {
                                    name "lower_arm_motor"
                                  }
                                ]
                                endPoint Solid {
                                  translation 0 -0.14 0.425
                                  rotation 0 1 0 0
                                  children [
                                    HingeJoint {
                                      jointParameters HingeJointParameters {
                                        axis 0 1 0
                                        anchor 0 0.14 0.8
                                      }
                                      device [
                                        PositionSensor {
                                          name "upper_arm_box_sensor"
                                        }
                                        RotationalMotor {
                                          name "upper_arm_box_motor"
                                        }
                                      ]
                                      endPoint Solid {
                                        translation 0 0.14 0.8
                                        rotation 0 1 0 0
                                        children [
                                          HingeJoint {
                                            jointParameters HingeJointParameters {
                                              axis 0 1 0
                                              anchor 0 0 0.47
                                            }
                                            device [
                                              RotationalMotor {
                                                name "upper_arm_motor"
                                              }
                                              PositionSensor {
                                                name "upper_arm_sensor"
                                              }
                                            ]
                                            endPoint Solid {
                                              translation 0 -0.14 0.47
                                              rotation 0 1 0 0
                                              children [
                                                Shape {
                                                  appearance PBRAppearance {
                                                    baseColor 0 0 0
                                                    metalness 0
                                                  }
                                                  geometry Mesh {
                                                    url [
                                                      "../protos/meshes/echoarm/8upper_arm.stl"
                                                    ]
                                                  }
                                                }
                                              ]
                                            }
                                          }
                                          Shape {
                                            appearance PBRAppearance {
                                              baseColor 0.447059 0.447059 0.447059
                                              metalness 0
                                            }
                                            geometry Mesh {
                                              url [
                                                "../protos/meshes/echoarm/7upper_arm_box.stl"
                                              ]
                                            }
                                          }
                                        ]
                                      }
                                    }
                                    Shape {
                                      appearance PBRAppearance {
                                        baseColor 0 0 0
                                        metalness 0
                                      }
                                      geometry Mesh {
                                        url [
                                          "../protos/meshes/echoarm/6lower_arm.stl"
                                        ]
                                      }
                                    }
                                  ]
                                }
                              }
                              Shape {
                                appearance PBRAppearance {
                                  baseColor 0.447059 0.447059 0.447059
                                  metalness 0
                                }
                                geometry Mesh {
                                  url [
                                    "../protos/meshes/echoarm/5elbow_box.stl"
                                  ]
                                }
                              }
                            ]
                            boundingObject Mesh {
                              url [
                                "../protos/meshes/echoarm/5elbow_box.stl"
                              ]
                            }
                          }
                        }
                        Shape {
                          appearance PBRAppearance {
                            baseColor 0.980392 0.980392 0.847059
                            metalness 0
                          }
                          geometry Mesh {
                            url [
                              "../protos/meshes/echoarm/4elbow_base.stl"
                            ]
                          }
                        }
                      ]
                      name "elbow"
                      boundingObject Mesh {
                        url [
                          "../protos/meshes/echoarm/4elbow_base.stl"
                        ]
                      }
                    }
                  }
                  Shape {
                    appearance PBRAppearance {
                      baseColor 0.776471 1 0.956863
                      metalness 0
                    }
                    geometry Mesh {
                      url [
                        "../protos/meshes/echoarm/3piston_base.stl"
                      ]
                    }
                  }
                ]
                name "piston_base"
                boundingObject Mesh {
                  url [
                    "../protos/meshes/echoarm/3piston_base.stl"
                  ]
                }
              }
            }
            Shape {
              appearance PBRAppearance {
                baseColor 0 0 0
                metalness 0
              }
              geometry Mesh {
                url [
                  "../protos/meshes/echoarm/2base_box.stl"
                ]
              }
            }
          ]
          name "base_box"
          boundingObject Mesh {
            url [
              "../protos/meshes/echoarm/2base_box.stl"
            ]
          }
        }
        Shape {
          appearance PBRAppearance {
            baseColor 0.980392 0.980392 0.847059
            metalness 0
          }
          geometry Mesh {
            url [
              "../protos/meshes/echoarm/1base.stl"
            ]
          }
        }
      ]
      name "Base"
      boundingObject Box {
        size 1 1 0.005
      }
      physics Physics {
      }
    }
  ]
  physics Physics {
  }
  controller "echoarm"
}
Robot {
  translation 0 -0.7 0.05
  children [
    SliderJoint {
      jointParameters JointParameters {
        axis 1 0 0
      }
      device [
        PositionSensor {
          name "sensor"
        }
        LinearMotor {
          name "motor"
        }
      ]
      endPoint Solid {
        translation 0 0 0.1
        children [
          Shape {
            geometry Sphere {
              radius 0.1
            }
          }
        ]
      }
    }
    Shape {
      geometry Box {
        size 1.5 0.1 0.1
      }
    }
  ]
  name "robot(1)"
  controller "my_controller"
}
