#VRML_SIM R2025a utf8

EXTERNPROTO "https://raw.githubusercontent.com/cyberbotics/webots/R2025a/projects/objects/backgrounds/protos/TexturedBackground.proto"
EXTERNPROTO "https://raw.githubusercontent.com/cyberbotics/webots/R2025a/projects/objects/backgrounds/protos/TexturedBackgroundLight.proto"
EXTERNPROTO "https://raw.githubusercontent.com/cyberbotics/webots/R2025a/projects/objects/apartment_structure/protos/Ceiling.proto"
EXTERNPROTO "https://raw.githubusercontent.com/cyberbotics/webots/R2025a/projects/objects/hospital/protos/EmergencyExitSign.proto"
EXTERNPROTO "https://raw.githubusercontent.com/cyberbotics/webots/R2025a/projects/appearances/protos/PaintedWood.proto"
EXTERNPROTO "https://raw.githubusercontent.com/cyberbotics/webots/R2025a/projects/humans/pedestrian/protos/Pedestrian.proto"
EXTERNPROTO "https://raw.githubusercontent.com/cyberbotics/webots/R2025a/projects/objects/hospital/protos/Curtain.proto"
EXTERNPROTO "https://raw.githubusercontent.com/cyberbotics/webots/R2025a/projects/objects/tables/protos/Table.proto"
EXTERNPROTO "https://raw.githubusercontent.com/cyberbotics/webots/R2025a/projects/objects/chairs/protos/OfficeChair.proto"
EXTERNPROTO "https://raw.githubusercontent.com/cyberbotics/webots/R2025a/projects/objects/computers/protos/DesktopComputer.proto"
EXTERNPROTO "https://raw.githubusercontent.com/cyberbotics/webots/R2025a/projects/objects/computers/protos/Monitor.proto"
EXTERNPROTO "https://raw.githubusercontent.com/cyberbotics/webots/R2025a/projects/objects/computers/protos/Keyboard.proto"
EXTERNPROTO "https://raw.githubusercontent.com/cyberbotics/webots/R2025a/projects/objects/computers/protos/ComputerMouse.proto"
EXTERNPROTO "https://raw.githubusercontent.com/cyberbotics/webots/R2025a/projects/objects/telephone/protos/OfficeTelephone.proto"
EXTERNPROTO "https://raw.githubusercontent.com/cyberbotics/webots/R2025a/projects/appearances/protos/Roughcast.proto"
EXTERNPROTO "https://raw.githubusercontent.com/cyberbotics/webots/R2025a/projects/objects/lights/protos/DoubleFluorescentLamp.proto"
EXTERNPROTO "https://raw.githubusercontent.com/cyberbotics/webots/R2025a/projects/objects/apartment_structure/protos/Door.proto"
EXTERNPROTO "https://raw.githubusercontent.com/cyberbotics/webots/R2025a/projects/objects/tables/protos/Desk.proto"
EXTERNPROTO "https://raw.githubusercontent.com/cyberbotics/webots/R2025a/projects/objects/apartment_structure/protos/WallPlug.proto"
EXTERNPROTO "https://raw.githubusercontent.com/cyberbotics/webots/R2025a/projects/objects/hospital/protos/HandSanitizer.proto"
EXTERNPROTO "https://raw.githubusercontent.com/cyberbotics/webots/R2025a/projects/objects/hospital/protos/MedicineBottle.proto"
EXTERNPROTO "https://raw.githubusercontent.com/cyberbotics/webots/R2025a/projects/objects/cabinet/protos/Cabinet.proto"
EXTERNPROTO "https://raw.githubusercontent.com/cyberbotics/webots/R2025a/projects/objects/factory/containers/protos/CardboardBox.proto"
EXTERNPROTO "https://raw.githubusercontent.com/cyberbotics/webots/R2025a/projects/objects/school_furniture/protos/Clock.proto"
EXTERNPROTO "https://raw.githubusercontent.com/cyberbotics/webots/R2025a/projects/objects/school_furniture/protos/Book.proto"
EXTERNPROTO "https://raw.githubusercontent.com/cyberbotics/webots/R2025a/projects/objects/traffic/protos/Pole.proto"
EXTERNPROTO "https://raw.githubusercontent.com/cyberbotics/webots/R2025a/projects/objects/television/protos/Television.proto"
EXTERNPROTO "https://raw.githubusercontent.com/cyberbotics/webots/R2025a/projects/objects/paintings/protos/PortraitPainting.proto"
EXTERNPROTO "https://raw.githubusercontent.com/cyberbotics/webots/R2025a/projects/objects/apartment_structure/protos/Wall.proto"
EXTERNPROTO "https://raw.githubusercontent.com/cyberbotics/webots/R2025a/projects/objects/animals/protos/Cow.proto"
EXTERNPROTO "https://raw.githubusercontent.com/cyberbotics/webots/R2025a/projects/objects/floors/protos/Floor.proto"

WorldInfo {
  title "echoarm_simulation"
}
Viewpoint {
  orientation -0.35684575771023797 -0.024083940071362043 0.9338528090844108 3.267479789069203
  position 1.889735847322208 -0.773964317449714 2.7816540688089453
}
TexturedBackground {
}
TexturedBackgroundLight {
  texture "noon_cloudy_empty"
}
Ceiling {
  translation 0 0 5
  appearance Roughcast {
    colorOverride 0.413382 0.417441 0.417441
    textureTransform TextureTransform {
      scale 10 10
    }
  }
}
Floor {
  tileSize 2 1
  appearance PaintedWood {
  }
}
DoubleFluorescentLamp {
  translation -1.16 -1.36539 5
  rotation 0.7071067811862364 -0.7071067811862364 9.381857096790023e-07 3.14159
}
DoubleFluorescentLamp {
  translation -1.16 -0.486124 5
  rotation 0.7071067811862364 -0.7071067811862364 9.381857096790023e-07 3.14159
  name "double fuorescent lamp(2)"
}
DoubleFluorescentLamp {
  translation -1.16 -0.913773 5
  rotation 0.7071067811862364 -0.7071067811862364 9.381857096790023e-07 3.14159
  name "double fuorescent lamp(3)"
}
DoubleFluorescentLamp {
  translation -1.16 -0.0776447 5
  rotation 0.7071067811862364 -0.7071067811862364 9.381857096790023e-07 3.14159
  name "double fuorescent lamp(4)"
}
DoubleFluorescentLamp {
  translation -1.14678 0.659562 5
  rotation 0.7071067811862364 -0.7071067811862364 9.381857096790023e-07 3.14159
  name "double fuorescent lamp(1)"
}
DoubleFluorescentLamp {
  translation -1.16 0.290508 5
  rotation 0.7071067811862364 -0.7071067811862364 9.381857096790023e-07 3.14159
  name "double fuorescent lamp(10)"
}
DoubleFluorescentLamp {
  translation 0.146758 0.304231 5
  rotation 0.7071067811862364 -0.7071067811862364 9.381857096790023e-07 3.14159
  name "double fuorescent lamp(5)"
}
DoubleFluorescentLamp {
  translation 0.15573 0.654182 5
  rotation 0.7071067811862364 -0.7071067811862364 9.381857096790023e-07 3.14159
  name "double fuorescent lamp(11)"
}
DoubleFluorescentLamp {
  translation 0.156641 -0.0586537 5
  rotation 0.7071067811862364 -0.7071067811862364 9.381857096790023e-07 3.14159
  name "double fuorescent lamp(6)"
}
DoubleFluorescentLamp {
  translation 0.133204 -0.474366 5
  rotation 0.7071067811862364 -0.7071067811862364 9.381857096790023e-07 3.14159
  name "double fuorescent lamp(7)"
}
DoubleFluorescentLamp {
  translation 0.122865 -1.34918 5
  rotation 0.7071067811862364 -0.7071067811862364 9.381857096790023e-07 3.14159
  name "double fuorescent lamp(8)"
}
DoubleFluorescentLamp {
  translation 1.47876 -0.902935 5
  rotation 0.7071067811862364 -0.7071067811862364 9.381857096790023e-07 3.14159
  name "double fuorescent lamp(12)"
}
DoubleFluorescentLamp {
  translation 1.4616 -0.0619357 5
  rotation 0.7071067811862364 -0.7071067811862364 9.381857096790023e-07 3.14159
  name "double fuorescent lamp(14)"
}
DoubleFluorescentLamp {
  translation 1.4616 0.298492 5
  rotation 0.7071067811862364 -0.7071067811862364 9.381857096790023e-07 3.14159
  name "double fuorescent lamp(16)"
}
DoubleFluorescentLamp {
  translation 1.4616 -0.465272 5
  rotation 0.7071067811862364 -0.7071067811862364 9.381857096790023e-07 3.14159
  name "double fuorescent lamp(15)"
}
DoubleFluorescentLamp {
  translation 0.146897 -0.91586 5
  rotation 0.7071067811862364 -0.7071067811862364 9.381857096790023e-07 3.14159
  name "double fuorescent lamp(9)"
}
DEF Muro1 Solid {
  translation 0 4.75 2.5
  children [
    Shape {
      appearance PaintedWood {
        colorOverride 0.74464 0.862104 1
      }
      geometry Box {
        size 10 0.5 5
      }
    }
  ]
  boundingObject Shape {
    appearance Appearance {
      material Material {
        ambientIntensity 0.7
        emissiveColor 0.7 0.7 0
      }
    }
    geometry Box {
      size 10 0.5 5
    }
  }
}
Door {
  translation -0.821541 4.65491 1.31955e-13
  rotation 0 0 1 -1.5707953071795862
  position -0.0019407029228525022
}
DEF Muro2 Solid {
  translation -5 0 2.5
  rotation -1.32199e-06 -1.33159e-06 1 1.57081
  children [
    Shape {
      appearance PaintedWood {
        colorOverride 0.74464 0.862104 1
      }
      geometry Box {
        size 10 0.5 5
      }
    }
  ]
  name "solid(1)"
  boundingObject Shape {
    appearance Appearance {
      material Material {
        ambientIntensity 0.7
        emissiveColor 0.7 0.7 0
      }
    }
    geometry Box {
      size 10 0.5 5
    }
  }
}
Curtain {
  translation -4.56 0.0849122 1.5
}
Curtain {
  translation -4.56156 1.51887 1.5
  name "curtain(2)"
}
Curtain {
  translation -4.57494 -2.79654 1.5
  name "curtain(3)"
}
Curtain {
  translation -4.54969 2.87899 1.5
  name "curtain(4)"
}
Curtain {
  translation -4.56596 -1.35865 1.5
  name "curtain(1)"
}
Solid {
  translation 0 0 -0.13
  children [
    Shape {
      appearance PBRAppearance {
        metalness 0
      }
      geometry Mesh {
        url [
          "../protos/meshes/lettino_piantana.stl"
        ]
      }
    }
  ]
  name "bed"
  boundingObject Shape {
    geometry Mesh {
      url [
        "../protos/meshes/lettino.stl"
      ]
    }
  }
}
EmergencyExitSign {
  translation -0.81 4.39 2.23
  rotation 1 0 0 1.5708
}
Cow {
  translation 2.6572 4.14 0.74
  rotation 0 0 1 -2.3561953071795863
  scale 0.1
}
Television {
  translation 1.28078 -1.0522 1.3
  rotation 0 0 -1 -0.523595307179586
  displayWidth 640
  displayHeight 480
  controller "tv"
}
Pole {
  translation 1.28997 -1.06903 -0.6000000029999799
}
Wall {
  translation -4.66 0.12 2.8
  size 0.1 7.5 0.05
}
Book {
  translation -2.316927738661737 4.165556500683838 0.48929365435670585
  rotation 0.5777365648217584 -0.5766681957439428 0.5776454394222978 2.092408746499705
}
Book {
  translation -3.105050799424049 4.179274309048965 0.4892936550495727
  rotation 0.5769495896169298 -0.5768394046398052 0.5782607303765762 2.0929279717098113
  name "book(2)"
}
Book {
  translation -2.309249599373026 4.190118578075092 0.5086295642755863
  rotation 0.5781220140617684 -0.5761007168089116 0.5778260126970945 2.090849204585879
  name "book(3)"
}
Book {
  translation -3.1186746537050043 4.200628269610884 0.5086386611544135
  rotation 0.5769372751062519 -0.5761685685333192 0.5789414143307066 2.0910772540678058
  name "book(6)"
}
Book {
  translation -2.319062731931711 4.190176059237857 0.5283084808155342
  rotation 0.5791886991667636 -0.5755218453582707 0.5773344405740254 2.089140062012756
  name "book(5)"
}
Book {
  translation -3.126042905055782 4.199983574463695 0.5478766563250365
  rotation 0.5841055473955991 -0.5626000930492266 0.5850656756319662 2.1083063412948535
  name "book(7)"
}
Book {
  translation -3.1053509257492404 4.214349531269792 0.5873542581098768
  rotation 0.6049472390417036 -0.5175376598937282 0.6051393298799405 2.177554399112319
  name "book(9)"
}
Book {
  translation -3.913558539522785 4.201460910055007 0.528560591421415
  rotation 0.573864125971434 -0.581418889727559 0.5767426112149289 2.0877891175244288
  name "book(10)"
}
Book {
  translation -2.2849083871917886 4.2072237045441305 0.5476713797833401
  rotation 0.5798301028911792 -0.575035419869654 0.5771752919837569 2.088864127823328
  name "book(11)"
}
Book {
  translation -2.2886024478426057 4.200807235348287 0.5674812994563557
  rotation 0.579659770557013 -0.5754288521843629 0.5769542325623217 2.0887822476486395
  name "book(12)"
}
Book {
  translation -3.104015924981089 4.231071714018271 0.5279899938067789
  rotation 0.5777185171781263 -0.5749302993254114 0.5793931875912071 2.091362068555843
  name "book(13)"
}
Book {
  translation -3.9111695714295167 4.20544890957947 0.5682404718375536
  rotation 0.5876225421315204 -0.5531582102557261 0.5905215850462806 2.1304133970749417
  name "book(15)"
}
Book {
  translation -3.063812023047141 4.256130310050183 0.5670299350141682
  rotation 0.5707259415444589 -0.5898443851696507 0.5712753284818345 2.0661123538083075
  name "book(16)"
}
Book {
  translation -2.296150569617734 4.180227038867599 0.587469682029812
  rotation 0.5795497087160991 -0.5756850146947949 0.5768092396823565 2.088603848645344
  name "book(17)"
}
Book {
  translation -3.8963177144294696 4.205011710784552 0.5483522324567577
  rotation 0.5683967652912479 -0.5920812070230519 0.5712836086363514 2.0718936797837713
  name "book(14)"
}
Book {
  translation -3.8908499041863487 4.192420282867247 0.5089823728341917
  rotation 0.5778049581044089 -0.5739573262643141 0.5802709867100732 2.0988166938984185
  name "book(8)"
}
Book {
  translation -3.925844933572871 4.187591005124462 0.3635350524946777
  rotation 0.32407976904679825 -0.4227674835584377 0.8463096112772441 2.035317373195133
  name "book(4)"
}
Book {
  translation -3.886050790784692 4.180488729272179 0.48941138836154796
  rotation 0.5679208494215615 -0.5944061797215483 0.5693392681882454 2.0694341307653
  name "book(1)"
}
Clock {
  translation -0.780073 4.49139 2.77
  rotation 0 0 1 -1.5707953071795862
}
CardboardBox {
  translation -1.90445 4.22871 1.6
  name "cardboard box(1)"
  size 0.4 0.4 0.2
}
CardboardBox {
  translation -2.32383 4.22843 1.6
  name "cardboard box(2)"
  size 0.4 0.4 0.2
}
CardboardBox {
  translation -2.8933 4.22039 1.6
  name "cardboard box(3)"
  size 0.6 0.4 0.2
}
CardboardBox {
  translation -2.43254 4.24574 1.85
  name "cardboard box(5)"
  size 0.6 0.4 0.3
}
CardboardBox {
  translation -3.55672 4.21996 1.6
  name "cardboard box(4)"
  size 0.6 0.4 0.6
}
DEF flacon MedicineBottle {
  translation -2.28512 4.26301 0.32
  name "medicine bottle(22)"
}
DEF flacon MedicineBottle {
  translation -2.339 4.12935 0.32
  name "medicine bottle(23)"
}
DEF flacon MedicineBottle {
  translation -2.20029 4.28808 0.32
  name "medicine bottle(24)"
}
DEF flacon MedicineBottle {
  translation -2.10799 4.29355 0.32
  name "medicine bottle(25)"
}
DEF flacon MedicineBottle {
  translation -2.23479 4.10823 0.32
  name "medicine bottle(26)"
}
DEF flacon MedicineBottle {
  translation -2.13218 4.12491 0.32
  name "medicine bottle(27)"
}
DEF flacon MedicineBottle {
  translation -2.04445 4.20653 0.32
  name "medicine bottle(28)"
}
Cabinet {
  translation -2.03706 4.49032 2.47305e-14
  rotation 0 0 1 -1.5707953071795862
  name "cabinet(2)"
}
Cabinet {
  translation -3.63218 4.49573 3.20343e-14
  rotation 0 0 1 -1.5707953071795862
}
Cabinet {
  translation -2.83745 4.49193 1.02783e-14
  rotation 0 0 1 -1.5707953071795862
  name "cabinet(1)"
}
DEF flacon MedicineBottle {
  translation 3.56926 4.39356 0.78
}
DEF flacon MedicineBottle {
  translation 3.69933 4.3255 0.78
  name "medicine bottle(6)"
}
DEF flacon MedicineBottle {
  translation 3.76588 4.32182 0.78
  name "medicine bottle(9)"
}
DEF flacon MedicineBottle {
  translation 3.9061 4.31311 0.78
  name "medicine bottle(10)"
}
DEF flacon MedicineBottle {
  translation 3.63443 4.3264 0.78
  name "medicine bottle(7)"
}
DEF flacon MedicineBottle {
  translation -2.87283 4.24044 0.32
  name "medicine bottle(12)"
}
DEF flacon MedicineBottle {
  translation -3.11988 4.12295 0.32
  name "medicine bottle(15)"
}
DEF flacon MedicineBottle {
  translation -3.91661 4.30275 0.32
  name "medicine bottle(16)"
}
DEF flacon MedicineBottle {
  translation -3.82355 4.33869 0.32
  name "medicine bottle(17)"
}
DEF flacon MedicineBottle {
  translation -3.91229 4.12358 0.32
  name "medicine bottle(18)"
}
DEF flacon MedicineBottle {
  translation -3.83771 4.17945 0.32
  name "medicine bottle(19)"
}
DEF flacon MedicineBottle {
  translation -3.74673 4.14264 0.32
  name "medicine bottle(20)"
}
DEF flacon MedicineBottle {
  translation -3.0661 4.22601 0.32
  name "medicine bottle(13)"
}
DEF flacon MedicineBottle {
  translation -2.96442 4.18594 0.32
  name "medicine bottle(14)"
}
DEF flacon MedicineBottle {
  translation -2.88014 4.09595 0.32
  name "medicine bottle(21)"
}
DEF flacon MedicineBottle {
  translation 3.84073 4.3196 0.78
  name "medicine bottle(8)"
}
DEF flacon MedicineBottle {
  translation 3.5709 4.32732 0.78
  name "medicine bottle(11)"
}
DEF flacon MedicineBottle {
  translation 3.63524 4.39233 0.78
  name "medicine bottle(1)"
}
DEF flacon MedicineBottle {
  translation 3.70087 4.39033 0.78
  name "medicine bottle(2)"
}
DEF flacon MedicineBottle {
  translation 3.76682 4.38993 0.78
  name "medicine bottle(3)"
}
DEF flacon MedicineBottle {
  translation 3.83551 4.38855 0.78
  name "medicine bottle(4)"
}
DEF flacon MedicineBottle {
  translation 3.89981 4.38844 0.78
  name "medicine bottle(5)"
}
HandSanitizer {
  translation -0.825129 1.05021 0.8
  rotation 0 0 1 0.785398
}
HandSanitizer {
  translation 0.579171 4.02396 0.81
  rotation 0 0 1 0.785398
  name "hand sanitizer(1)"
}
WallPlug {
  translation 1.19778 4.54094 0.84
  rotation 0 0 1 -1.5707953071795862
}
WallPlug {
  translation 1.27 4.54078 0.84
  rotation 0 0 1 -1.5707953071795862
  name "wall plug(1)"
}
WallPlug {
  translation 1.34 4.54078 0.84
  rotation 0 0 1 -1.5707953071795862
  name "wall plug(2)"
}
Desk {
  translation -0.68355 0.636776 -5.96647e-14
}
DoubleFluorescentLamp {
  translation 1.44444 0.650338 5
  rotation 0.7071067811862364 -0.7071067811862364 9.381857096790023e-07 3.14159
  name "double fuorescent lamp(17)"
}
DoubleFluorescentLamp {
  translation 1.4616 -1.34918 5
  rotation 0.7071067811862364 -0.7071067811862364 9.381857096790023e-07 3.14159
  name "double fuorescent lamp(13)"
}
OfficeChair {
  translation 1.0820208527118855 3.070380481952456 -0.0014153342692832804
  rotation 0.0006835510719184197 -0.002627707204976228 0.9999963139495951 0.5236008691926578
  name "office chair(2)"
}
Monitor {
  translation 2.00601 4.24785 0.75
  rotation 0 0 -1 1.8326
}
DesktopComputer {
  translation 1.02629 4.20872 0.75
  rotation 0 0 1 -1.5707953071795862
}
OfficeChair {
  translation 2.2924491562630416 2.9694504974973888 -0.0014153342692832527
  rotation 0.0007013427504804083 -0.0001934297241507683 0.999999735351609 2.617990158485274
}
OfficeChair {
  translation 3.417460008969493 3.089520979446411 -0.0014153342692831972
  rotation 0.0006975832860799852 -0.0007078513569368525 0.9999995061618858 1.5708005199984858
  name "office chair(1)"
}
Table {
  translation 3.11466 3.98761 2.98877e-14
  rotation 0 0 1 1.5708
  name "table(1)"
}
OfficeTelephone {
  translation 2.4404467696850616 4.153977771874084 0.7431580860563192
  rotation 0.0007225956915626094 -0.0001366734882123893 -0.9999997295878756 1.5707963591007428
}
Monitor {
  translation -0.745569 0.351457 0.71
  rotation 0 0 1 0.5236
  name "monitor ecografia"
}
Monitor {
  translation 1.53481 4.30841 0.75
  rotation 0 0 1 -1.5707953071795862
  name "monitor(2)"
}
Table {
  translation 1.32302 3.98419 3.01541e-14
  rotation 0 0 1 1.5708
}
ComputerMouse {
  translation -0.6722354120757802 0.7136541373060874 0.7099607602670769
  rotation 4.918552455100075e-07 -1.8366025516045829e-06 0.9999999999981926 -2.6182589925174913
  name "computer ecografia mouse"
}
ComputerMouse {
  translation 1.8903 3.96342 0.7399607602671671
  rotation -2.3806401850969693e-06 -1.8366025518048121e-06 0.9999999999954796 1.314207117582323
  name "computer mouse(1)"
}
Keyboard {
  translation 1.54008 4.01052 0.75
  rotation 0 0 1 -1.5707953071795862
}
Keyboard {
  translation -0.526682 0.448736 0.71
  rotation 0 0 1 -2.6179953071795863
  name "keyboard ecografia"
}
Pedestrian {
  translation 1.1359999999999988 1.28 1.2579999999999993
  rotation 0 0 1 3.141592653589793
  name "doctor"
  controllerArgs [
    "--trajectory=\"0.92 1.28,1.78 1.28\" --speed=0.5 --pause_duration=3.0"
  ]
  shirtColor 0.291752 0.598627 0.655756
  pantsColor 0.219608 0.407965 0.525383
  shoesColor 0 0 0
  rightLegAngle -0.7719999999999974
  rightLowerLegAngle 0.6896363636363565
  rightFootAngle -0.31254545454545624
  leftLegAngle 0.37381818181818277
  leftLowerLegAngle 0.24036363636363708
  leftFootAngle -0.006181818181820453
  rightArmAngle 0.680363636363637
  rightLowerArmAngle -0.4323636363636345
  rightHandAngle 0.18690909090909139
  leftArmAngle -0.677818181818184
  leftLowerArmAngle -0.27054545454545237
  leftHandAngle -0.04090909090908945
  headAngle 0.0752727272727278
}
DEF CAMERA Robot {
  translation -0.03 -0.37 3.45
  children [
    Emitter {
      channel 1
    }
    SpotLight {
      attenuation 0 0 1
      beamWidth 0
      cutOffAngle 0.5
      direction 0 0 -2
      intensity 7
    }
    DEF ZENIT_CAMERA Camera {
      translation -8.87054e-07 -4.61711e-06 0.87
      rotation 0.7071072811853203 1.8797507474938104e-06 -0.7071062811849226 -3.1415853071795863
      children [
        RangeFinder {
          fieldOfView 0.8
          width 640
          height 480
          maxRange 15
        }
      ]
      fieldOfView 0.8
      width 640
      height 480
    }
    Solid {
      boundingObject Box {
        size 0.1 0.1 0.1
      }
    }
  ]
  name "camera"
  controller "camera"
}
Pose {
  translation 0.95 -0.45 0.9
  rotation 0 0 1 1.5708
  children [
    CadShape {
      url [
        "../protos/meshes/patient_2.obj"
        "omino"
      ]
    }
  ]
}
DEF ECHOARM Robot {
  translation 0 -1.7 0.85
  children [
    Receiver {
      channel 1
    }
    DEF JOINT_SLIDER_BASE SliderJoint {
      jointParameters JointParameters {
        axis 1 0 0
        minStop -0.8
        maxStop 0.8
      }
      device [
        PositionSensor {
          name "slider_base_sensor"
        }
        LinearMotor {
          name "slider_piston_base"
          maxVelocity 5
          minPosition -0.8
          maxPosition 0.8
        }
      ]
      endPoint DEF LINK_SLIDER_BASE Solid {
        children [
          Solid {
            translation 0 0.35 0.2
            children [
              DEF JOINT_PISTON SliderJoint {
                jointParameters JointParameters {
                  axis 0 1 0
                  maxStop 0.07
                }
                device [
                  PositionSensor {
                    name "piston_sensor"
                  }
                  LinearMotor {
                    name "piston_motor"
                  }
                ]
                endPoint DEF LINK_PISTON Solid {
                  translation 0 0.04 0
                  children [
                    DEF JOINT_ELBOW HingeJoint {
                      jointParameters HingeJointParameters {
                        axis 0 1 0
                        anchor 0 0.17 0
                      }
                      device [
                        RotationalMotor {
                          name "elbow_motor"
                        }
                        PositionSensor {
                          name "elbow_position"
                        }
                      ]
                      endPoint DEF LINK_ELBOW Solid {
                        translation 0 0.17 0
                        rotation 0 1 0 0
                        children [
                          DEF JOINT_LOWER_ARM_ROTATION HingeJoint {
                            jointParameters HingeJointParameters {
                              axis 0 0 1
                              anchor 0 0.075 0.0736
                            }
                            device [
                              RotationalMotor {
                                name "lower_arm_rotation_motor"
                              }
                              PositionSensor {
                                name "lower_arm_rotation_sensor"
                              }
                            ]
                            endPoint DEF LINK_LOWER_ARM_ROTATION Solid {
                              translation 0 0.075 0.0736
                              rotation 1 0 0 1.5708003061004252
                              children [
                                DEF JOINT_LOWER_ARM_VERTICAL HingeJoint {
                                  jointParameters HingeJointParameters {
                                    position 1.57
                                    anchor 0 0.06 0
                                  }
                                  device [
                                    PositionSensor {
                                      name "lower_arm_vertical_sensor"
                                    }
                                    RotationalMotor {
                                      name "lower_arm_vertical_motor"
                                    }
                                  ]
                                  endPoint DEF LINK_LOWER_ARM_VERTICAL Solid {
                                    translation 0.035 0.06 0
                                    rotation -0.00039521865680989117 0.00039816335583172773 0.9999998426340653 1.5707935371198234
                                    children [
                                      HingeJoint {
                                        jointParameters HingeJointParameters {
                                          position 1.57
                                          axis 0 1 0
                                          anchor 0.36 0.035 0
                                        }
                                        device [
                                          RotationalMotor {
                                            name "lower_upper_arm_rotation_motor"
                                          }
                                          PositionSensor {
                                            name "lower_upper_arm_rotation_sensor"
                                          }
                                        ]
                                        endPoint Solid {
                                          translation 0.36003981633553667 0.035 -0.04999998414659172
                                          rotation 0.5771976613402439 0.5771955411787425 0.5776574824121401 2.0939375257929127
                                          children [
                                            HingeJoint {
                                              jointParameters HingeJointParameters {
                                                axis 0 1 0
                                              }
                                              device [
                                                RotationalMotor {
                                                  name "upper_arm_rotation_motor"
                                                }
                                                PositionSensor {
                                                  name "upper_arm_rotation_sensor"
                                                }
                                              ]
                                              endPoint Solid {
                                                translation -2.06647e-15 0.01 0
                                                rotation 0 0 1 3.14159
                                                children [
                                                  HingeJoint {
                                                    jointParameters HingeJointParameters {
                                                      position -1.57
                                                      anchor 0 0.06 0
                                                    }
                                                    device [
                                                      RotationalMotor {
                                                        name "upper_arm_vertical_motor"
                                                      }
                                                      PositionSensor {
                                                        name "upper_arm_vertical_sensor"
                                                      }
                                                    ]
                                                    endPoint Solid {
                                                      translation 0.035 0.060000000079632666 -9.999996829605904e-08
                                                      rotation -0.5771955411787425 0.5771976613402439 0.5776574824121401 2.0939375257929127
                                                      children [
                                                        HingeJoint {
                                                          jointParameters HingeJointParameters {
                                                            axis 0 1 0
                                                            anchor 0.35 0 0
                                                          }
                                                          device [
                                                            RotationalMotor {
                                                              name "probe_motor"
                                                            }
                                                            PositionSensor {
                                                              name "probe_sensor"
                                                            }
                                                          ]
                                                          endPoint Solid {
                                                            translation 0.33 -0.0155 -0.0075
                                                            rotation 0 0 -0.9999999999999999 1.5707953071795862
                                                            children [
                                                              Shape {
                                                                appearance PBRAppearance {
                                                                  metalness 0
                                                                }
                                                                geometry Mesh {
                                                                  url [
                                                                    "../protos/meshes/echoarm/probe.stl"
                                                                  ]
                                                                }
                                                              }
                                                            ]
                                                            boundingObject Mesh {
                                                              url [
                                                                "../protos/meshes/echoarm/probe.stl"
                                                              ]
                                                            }
                                                          }
                                                        }
                                                        Shape {
                                                          appearance PBRAppearance {
                                                          }
                                                          geometry Mesh {
                                                            url [
                                                              "../protos/meshes/echoarm/UpperArm.stl"
                                                            ]
                                                          }
                                                        }
                                                      ]
                                                      boundingObject Mesh {
                                                        url [
                                                          "../protos/meshes/echoarm/UpperArm.stl"
                                                        ]
                                                      }
                                                    }
                                                  }
                                                  Shape {
                                                    appearance PBRAppearance {
                                                    }
                                                    geometry Mesh {
                                                      url [
                                                        "../protos/meshes/echoarm/UpperArmVertical.stl"
                                                      ]
                                                    }
                                                  }
                                                ]
                                                boundingObject Mesh {
                                                  url [
                                                    "../protos/meshes/echoarm/UpperArmVertical.stl"
                                                  ]
                                                }
                                              }
                                            }
                                            Shape {
                                              appearance PBRAppearance {
                                              }
                                              geometry Mesh {
                                                url [
                                                  "../protos/meshes/echoarm/UpperArmRotation.stl"
                                                ]
                                              }
                                            }
                                          ]
                                          boundingObject Mesh {
                                            url [
                                              "../protos/meshes/echoarm/UpperArmRotation.stl"
                                            ]
                                          }
                                        }
                                      }
                                      Shape {
                                        appearance PBRAppearance {
                                        }
                                        geometry Mesh {
                                          url [
                                            "../protos/meshes/echoarm/LowerArm.stl"
                                          ]
                                        }
                                      }
                                    ]
                                    boundingObject Mesh {
                                      url [
                                        "../protos/meshes/echoarm/LowerArm.stl"
                                      ]
                                    }
                                  }
                                }
                                Shape {
                                  appearance PBRAppearance {
                                  }
                                  geometry Mesh {
                                    url [
                                      "../protos/meshes/echoarm/LowerArmRotation.stl"
                                    ]
                                  }
                                }
                              ]
                              boundingObject Mesh {
                                url [
                                  "../protos/meshes/echoarm/LowerArmRotation.stl"
                                ]
                              }
                            }
                          }
                          Shape {
                            appearance PBRAppearance {
                            }
                            geometry Mesh {
                              url [
                                "../protos/meshes/echoarm/LowerElbow.stl"
                              ]
                            }
                          }
                        ]
                        boundingObject Mesh {
                          url [
                            "../protos/meshes/echoarm/LowerElbow.stl"
                          ]
                        }
                      }
                    }
                    Shape {
                      appearance PBRAppearance {
                      }
                      geometry Mesh {
                        url [
                          "../protos/meshes/echoarm/piston+elbow_box.stl"
                        ]
                      }
                    }
                  ]
                  name "LINK_PISTON"
                  boundingObject Mesh {
                    url [
                      "../protos/meshes/echoarm/piston+elbow_box.stl"
                    ]
                  }
                }
              }
              Shape {
                appearance PBRAppearance {
                }
                geometry Mesh {
                  url [
                    "../protos/meshes/echoarm/base+box.stl"
                  ]
                }
              }
            ]
            name "base_and_box"
            boundingObject Mesh {
              url [
                "../protos/meshes/echoarm/base+box.stl"
              ]
            }
          }
          Shape {
            appearance Appearance {
              material Material {
              }
              texture ImageTexture {
              }
            }
            geometry Box {
              size 0.4 0.15 0.8
            }
          }
        ]
      }
    }
    Shape {
      appearance PBRAppearance {
      }
      geometry Box {
        size 1.9 0.15 0.05
      }
    }
  ]
  name "echoarm"
  controller "ultrasound"
  supervisor TRUE
}
PortraitPainting {
  translation 1.07 4.47 2.275
  rotation 0 0 1 -1.5707953071795862
  textureUrl [
    "../textures/anatomy.jpg"
  ]
}
