#VRML_SIM R2025a utf8

EXTERNPROTO "https://raw.githubusercontent.com/cyberbotics/webots/R2025a/projects/objects/backgrounds/protos/TexturedBackground.proto"
EXTERNPROTO "https://raw.githubusercontent.com/cyberbotics/webots/R2025a/projects/objects/backgrounds/protos/TexturedBackgroundLight.proto"
EXTERNPROTO "https://raw.githubusercontent.com/cyberbotics/webots/R2025a/projects/objects/floors/protos/Floor.proto"
EXTERNPROTO "https://raw.githubusercontent.com/cyberbotics/webots/R2025a/projects/objects/apartment_structure/protos/Ceiling.proto"
EXTERNPROTO "https://raw.githubusercontent.com/cyberbotics/webots/R2025a/projects/objects/hospital/protos/EmergencyExitSign.proto"
EXTERNPROTO "https://raw.githubusercontent.com/cyberbotics/webots/R2025a/projects/appearances/protos/PaintedWood.proto"
EXTERNPROTO "https://raw.githubusercontent.com/cyberbotics/webots/R2025a/projects/humans/pedestrian/protos/Pedestrian.proto"
EXTERNPROTO "https://raw.githubusercontent.com/cyberbotics/webots/R2025a/projects/objects/hospital/protos/Curtain.proto"
EXTERNPROTO "https://raw.githubusercontent.com/cyberbotics/webots/R2025a/projects/objects/tables/protos/Table.proto"
EXTERNPROTO "https://raw.githubusercontent.com/cyberbotics/webots/R2025a/projects/objects/chairs/protos/OfficeChair.proto"
EXTERNPROTO "https://raw.githubusercontent.com/cyberbotics/webots/R2025a/projects/objects/computers/protos/DesktopComputer.proto"
EXTERNPROTO "https://raw.githubusercontent.com/cyberbotics/webots/R2025a/projects/objects/computers/protos/Monitor.proto"
EXTERNPROTO "https://raw.githubusercontent.com/cyberbotics/webots/R2025a/projects/objects/computers/protos/Keyboard.proto"
EXTERNPROTO "https://raw.githubusercontent.com/cyberbotics/webots/R2025a/projects/objects/computers/protos/ComputerMouse.proto"
EXTERNPROTO "https://raw.githubusercontent.com/cyberbotics/webots/R2025a/projects/objects/telephone/protos/OfficeTelephone.proto"
EXTERNPROTO "https://raw.githubusercontent.com/cyberbotics/webots/R2025a/projects/appearances/protos/Roughcast.proto"
EXTERNPROTO "https://raw.githubusercontent.com/cyberbotics/webots/R2025a/projects/objects/lights/protos/DoubleFluorescentLamp.proto"
EXTERNPROTO "https://raw.githubusercontent.com/cyberbotics/webots/R2025a/projects/objects/apartment_structure/protos/Door.proto"
EXTERNPROTO "https://raw.githubusercontent.com/cyberbotics/webots/R2025a/projects/objects/tables/protos/Desk.proto"
EXTERNPROTO "https://raw.githubusercontent.com/cyberbotics/webots/R2025a/projects/objects/apartment_structure/protos/WallPlug.proto"
EXTERNPROTO "https://raw.githubusercontent.com/cyberbotics/webots/R2025a/projects/objects/hospital/protos/HandSanitizer.proto"
EXTERNPROTO "https://raw.githubusercontent.com/cyberbotics/webots/R2025a/projects/objects/hospital/protos/MedicineBottle.proto"
EXTERNPROTO "https://raw.githubusercontent.com/cyberbotics/webots/R2025a/projects/objects/cabinet/protos/Cabinet.proto"
EXTERNPROTO "https://raw.githubusercontent.com/cyberbotics/webots/R2025a/projects/objects/factory/containers/protos/CardboardBox.proto"
EXTERNPROTO "https://raw.githubusercontent.com/cyberbotics/webots/R2025a/projects/objects/school_furniture/protos/Clock.proto"
EXTERNPROTO "https://raw.githubusercontent.com/cyberbotics/webots/R2025a/projects/objects/school_furniture/protos/Book.proto"
EXTERNPROTO "https://raw.githubusercontent.com/cyberbotics/webots/R2025a/projects/objects/traffic/protos/Pole.proto"
EXTERNPROTO "https://raw.githubusercontent.com/cyberbotics/webots/R2025a/projects/objects/television/protos/Television.proto"

WorldInfo {
}
Viewpoint {
  orientation 0.35078753390202255 0.0022341887600346414 -0.9364524090734788 3.0837732921311143
  position 6.474728440547544 -1.0173410797844458 6.8193062943179426
}
TexturedBackground {
}
TexturedBackgroundLight {
  texture "noon_cloudy_empty"
}
Ceiling {
  translation 0 0 5
  appearance Roughcast {
    colorOverride 0.413382 0.417441 0.417441
    textureTransform TextureTransform {
      scale 10 10
    }
  }
}
DoubleFluorescentLamp {
  translation -1.16 -1.36539 5
  rotation 0.7071067811862364 -0.7071067811862364 9.381857096790023e-07 3.14159
}
DoubleFluorescentLamp {
  translation -1.16 -0.486124 5
  rotation 0.7071067811862364 -0.7071067811862364 9.381857096790023e-07 3.14159
  name "double fuorescent lamp(2)"
}
DoubleFluorescentLamp {
  translation -1.16 -0.913773 5
  rotation 0.7071067811862364 -0.7071067811862364 9.381857096790023e-07 3.14159
  name "double fuorescent lamp(3)"
}
DoubleFluorescentLamp {
  translation -1.16 -0.0776447 5
  rotation 0.7071067811862364 -0.7071067811862364 9.381857096790023e-07 3.14159
  name "double fuorescent lamp(4)"
}
DoubleFluorescentLamp {
  translation -1.14678 0.659562 5
  rotation 0.7071067811862364 -0.7071067811862364 9.381857096790023e-07 3.14159
  name "double fuorescent lamp(1)"
}
DoubleFluorescentLamp {
  translation -1.16 0.290508 5
  rotation 0.7071067811862364 -0.7071067811862364 9.381857096790023e-07 3.14159
  name "double fuorescent lamp(10)"
}
DoubleFluorescentLamp {
  translation 0.146758 0.304231 5
  rotation 0.7071067811862364 -0.7071067811862364 9.381857096790023e-07 3.14159
  name "double fuorescent lamp(5)"
}
DoubleFluorescentLamp {
  translation 0.15573 0.654182 5
  rotation 0.7071067811862364 -0.7071067811862364 9.381857096790023e-07 3.14159
  name "double fuorescent lamp(11)"
}
DoubleFluorescentLamp {
  translation 0.156641 -0.0586537 5
  rotation 0.7071067811862364 -0.7071067811862364 9.381857096790023e-07 3.14159
  name "double fuorescent lamp(6)"
}
DoubleFluorescentLamp {
  translation 0.133204 -0.474366 5
  rotation 0.7071067811862364 -0.7071067811862364 9.381857096790023e-07 3.14159
  name "double fuorescent lamp(7)"
}
DoubleFluorescentLamp {
  translation 0.122865 -1.34918 5
  rotation 0.7071067811862364 -0.7071067811862364 9.381857096790023e-07 3.14159
  name "double fuorescent lamp(8)"
}
DoubleFluorescentLamp {
  translation 1.47876 -0.902935 5
  rotation 0.7071067811862364 -0.7071067811862364 9.381857096790023e-07 3.14159
  name "double fuorescent lamp(12)"
}
DoubleFluorescentLamp {
  translation 1.4616 -0.0619357 5
  rotation 0.7071067811862364 -0.7071067811862364 9.381857096790023e-07 3.14159
  name "double fuorescent lamp(14)"
}
DoubleFluorescentLamp {
  translation 1.4616 0.298492 5
  rotation 0.7071067811862364 -0.7071067811862364 9.381857096790023e-07 3.14159
  name "double fuorescent lamp(16)"
}
DoubleFluorescentLamp {
  translation 1.4616 -0.465272 5
  rotation 0.7071067811862364 -0.7071067811862364 9.381857096790023e-07 3.14159
  name "double fuorescent lamp(15)"
}
DoubleFluorescentLamp {
  translation 0.146897 -0.91586 5
  rotation 0.7071067811862364 -0.7071067811862364 9.381857096790023e-07 3.14159
  name "double fuorescent lamp(9)"
}
DEF Muro1 Solid {
  translation 0 4.75 2.5
  children [
    Shape {
      appearance PaintedWood {
        colorOverride 0.74464 0.862104 1
      }
      geometry Box {
        size 10 0.5 5
      }
    }
  ]
  boundingObject Shape {
    appearance Appearance {
      material Material {
        ambientIntensity 0.7
        emissiveColor 0.7 0.7 0
      }
    }
    geometry Box {
      size 10 0.5 5
    }
  }
}
Door {
  hidden translation_5 0.0012131282724002768 6.680246204743279e-05 1.2212453270876722e-15
  hidden rotation_5 0 0 -1 0.00044865954412841763
  hidden linearVelocity_5 -3.6507590883623705e-19 -6.9369526558142185e-18 -1.168265512874667e-15
  hidden angularVelocity_5 -2.0507586625036583e-19 2.098070126634438e-18 -1.41969332036461e-17
  translation -0.821541 4.65491 1.31955e-13
  rotation 0 0 1 -1.5707953071795862
  position -0.0017944923025006066
}
DEF Muro2 Solid {
  translation -5 0 2.5
  rotation -1.32199e-06 -1.33159e-06 1 1.57081
  children [
    Shape {
      appearance PaintedWood {
        colorOverride 0.74464 0.862104 1
      }
      geometry Box {
        size 10 0.5 5
      }
    }
  ]
  name "solid(1)"
  boundingObject Shape {
    appearance Appearance {
      material Material {
        ambientIntensity 0.7
        emissiveColor 0.7 0.7 0
      }
    }
    geometry Box {
      size 10 0.5 5
    }
  }
}
Curtain {
  translation -4.5 0.0849122 1.5
}
Curtain {
  translation -4.50156 1.51887 1.5
  name "curtain(2)"
}
Curtain {
  translation -4.49494 -2.79654 1.5
  name "curtain(3)"
}
Curtain {
  translation -4.50969 2.87899 1.5
  name "curtain(4)"
}
Curtain {
  translation -4.49596 -1.35865 1.5
  name "curtain(1)"
}
Solid {
  translation 0 0 -0.13
  children [
    Shape {
      appearance PBRAppearance {
        metalness 0
      }
      geometry Mesh {
        url [
          "../protos/meshes/lettino_piantana.stl"
        ]
      }
    }
  ]
  name "bed"
  boundingObject Shape {
    geometry Mesh {
      url [
        "../protos/meshes/lettino.stl"
      ]
    }
  }
}
EmergencyExitSign {
  translation -0.81 4.39 2.23
  rotation 1 0 0 1.5708
}
Floor {
  tileSize 2 1
  appearance PaintedWood {
  }
}
Television {
  translation 1.32404 -1.0272 1.3
  rotation 0 0 -1 -0.523595307179586
}
Pole {
  translation 1.28997 -1.06903 -0.6000000029999799
}
Book {
  hidden linearVelocity_0 4.764704151863082e-08 4.000266236532867e-08 -1.650189668396378e-06
  hidden angularVelocity_0 -3.999049932527155e-06 4.762331484612909e-06 -2.463947142863063e-09
  translation -2.316927745182684 4.165556495681882 0.489293858486741
  rotation 0.5777364099343031 -0.5766684179006084 0.5776453725532925 2.0924094120639025
}
Book {
  hidden linearVelocity_0 5.214213564865887e-09 5.8771536460589944e-08 -1.6490369676110567e-06
  hidden angularVelocity_0 -5.875000942071354e-06 5.204334942545146e-07 -5.019080139345657e-10
  translation -3.105050800140995 4.179274301681178 0.48929385894209043
  rotation 0.576949704139422 -0.5768395606113655 0.5782604605254629 2.092928438323737
  name "book(2)"
}
Book {
  hidden linearVelocity_0 2.99289314872061e-07 2.465647593814307e-07 -3.2110385924020383e-06
  hidden angularVelocity_0 -6.960273257855797e-06 8.942398771765703e-06 -4.632566713946489e-08
  translation -2.3092496914294385 4.1901185030177865 0.508629962429535
  rotation 0.5781217099509361 -0.5761011151081313 0.5778259198535259 2.0908504359978286
  name "book(3)"
}
Book {
  hidden linearVelocity_0 8.265229252869555e-08 3.8910018004041573e-07 -3.1803991867697284e-06
  hidden angularVelocity_0 -1.1345772853886944e-05 3.16257918257321e-06 1.2559675621925765e-09
  translation -3.1186746827988374 4.200628148855917 0.5086390545924822
  rotation 0.5769373934682597 -0.5761689235008104 0.578940943110753 2.0910783090398097
  name "book(6)"
}
Book {
  hidden linearVelocity_0 9.361762410179811e-07 4.3138030864497445e-07 -8.028968622729285e-06
  hidden angularVelocity_0 -7.309531271564893e-06 5.021135244679646e-05 -4.487968814817493e-08
  translation -2.319063060354095 4.190175941354744 0.5283111688360096
  rotation 0.5791812924686138 -0.5755258393169239 0.5773378895698225 2.0891519257285665
  name "book(5)"
}
Book {
  hidden linearVelocity_0 4.502848087815707e-07 1.1518598993837608e-06 -4.94616263892982e-06
  hidden angularVelocity_0 -1.3970017640576107e-05 9.645813345236522e-06 2.0805865422949337e-07
  translation -3.1260430336823415 4.199983244875269 0.5478772676686143
  rotation 0.5841053838921314 -0.5626007281158472 0.5850652281854944 2.108307977742614
  name "book(7)"
}
Book {
  hidden linearVelocity_0 1.0148616881786053e-06 1.8407730901107557e-06 -6.185834847656137e-06
  hidden angularVelocity_0 -1.3616280650799842e-05 1.1105858178940208e-05 2.700213987465351e-07
  translation -3.105351170269963 4.214349059477429 0.5873550236187913
  rotation 0.6049469583143388 -0.5175383696891775 0.6051390034741588 2.1775560611849865
  name "book(9)"
}
Book {
  hidden linearVelocity_0 -2.958149156285713e-07 3.4666029541456394e-07 -3.3821324679195706e-06
  hidden angularVelocity_0 -6.731789037791526e-06 -5.364579635135894e-06 1.0464484640090767e-07
  translation -3.9135584633794482 4.201460816367129 0.5285610116854806
  rotation 0.5738645404897645 -0.5814189430107882 0.5767421450498388 2.0877891741182784
  name "book(10)"
}
Book {
  hidden linearVelocity_0 2.098890824797602e-06 6.325228504908605e-07 -1.0746831592835177e-05
  hidden angularVelocity_0 -7.090177161253188e-06 5.355479447080072e-05 4.627951566753266e-08
  translation -2.2849091898753238 4.207223534051109 0.5476748652663338
  rotation 0.5798225010507162 -0.5750395249300008 0.5771788388736813 2.0888762046986864
  name "book(11)"
}
Book {
  hidden linearVelocity_0 3.2579855743176403e-06 8.013458786265028e-07 -1.1055493733114545e-05
  hidden angularVelocity_0 -6.311878515502365e-06 5.3078652846610114e-05 1.2503739941837718e-07
  translation -2.2886037070011187 4.200807028040008 0.5674847731094569
  rotation 0.5796521601681468 -0.5754329450833259 0.576957796485264 2.0887942253345546
  name "book(12)"
}
Book {
  hidden linearVelocity_0 2.3781227975152174e-07 7.745617080754118e-07 -4.715123080719537e-06
  hidden angularVelocity_0 -1.2959891983896895e-05 6.08841293811881e-06 8.557764152702065e-08
  translation -3.104016002483135 4.231071479248711 0.5279905780418241
  rotation 0.5777185232501485 -0.5749307855678311 0.579392699039282 2.0913634252164783
  name "book(13)"
}
Book {
  hidden linearVelocity_0 -5.493256326389525e-07 6.711333729325085e-07 -4.132047518510449e-06
  hidden angularVelocity_0 -6.8443814535035505e-06 -5.578149371986461e-06 1.0638613277064221e-07
  translation -3.911169445457025 4.205448751779567 0.5682409850792839
  rotation 0.5876229582346078 -0.5531582737295853 0.5905211115278721 2.130413476791417
  name "book(15)"
}
Book {
  hidden linearVelocity_0 7.27430449242301e-07 1.525380210237587e-06 -7.004136179631647e-06
  hidden angularVelocity_0 -1.4663370371174534e-05 1.2976829562611603e-05 2.664588450101249e-07
  translation -3.063812212297305 4.256129889463987 0.5670308040485951
  rotation 0.5707256503042791 -0.589845107429726 0.5712748737043951 2.066114273038799
  name "book(16)"
}
Book {
  hidden linearVelocity_0 4.3705869331709576e-06 9.400617720084608e-07 -1.0803568800999522e-05
  hidden angularVelocity_0 -5.963667283926802e-06 5.2898037260398963e-05 1.5908134263247703e-07
  translation -2.29615226074499 4.180226807252946 0.5874730220542892
  rotation 0.5795420942273685 -0.5756891021417301 0.576812810792032 2.088615784333435
  name "book(17)"
}
Book {
  hidden linearVelocity_0 -4.31063966754998e-07 5.231742709808523e-07 -3.865734442172122e-06
  hidden angularVelocity_0 -6.851125869563357e-06 -5.2402266499938846e-06 1.1182627394137873e-07
  translation -3.8963176080434336 4.20501157665678 0.5483527124918909
  rotation 0.5683971804692473 -0.5920812631331052 0.5712831374032641 2.0718937397904686
  name "book(14)"
}
Book {
  hidden linearVelocity_0 -1.5400803791071112e-07 1.6458038924336312e-07 -2.387568535340114e-06
  hidden angularVelocity_0 -6.048742000455871e-06 -4.3253706301907346e-06 9.965002875392158e-08
  translation -3.8908498664180287 4.192420236842845 0.5089826694034334
  rotation 0.5778053029798808 -0.573957390276009 0.5802705799847874 2.0988167857369744
  name "book(8)"
}
Book {
  hidden linearVelocity_0 2.013867309849837e-06 -5.82571054585186e-07 -2.914320466231863e-06
  hidden angularVelocity_0 7.336596245393292e-05 -2.7784241767595774e-05 2.5331921506759776e-05
  translation -3.9258458144344224 4.18759081799112 0.3635360399341829
  rotation 0.3240767989816192 -0.42275528105176735 0.8463168441574753 2.0352936059231945
  name "book(4)"
}
Book {
  hidden linearVelocity_0 -3.514883799069511e-08 2.414701168627978e-08 -1.380091750604497e-06
  hidden angularVelocity_0 -2.4139942448746682e-06 -3.514261702024531e-06 9.499457556358581e-10
  translation -3.886050786375821 4.180488726246783 0.4894115597117619
  rotation 0.567921080022077 -0.594406150859633 0.5693390682948016 2.0694340404545475
  name "book(1)"
}
Clock {
  translation -0.780073 4.49139 2.77
  rotation 0 0 1 -1.5707953071795862
}
CardboardBox {
  translation -1.90445 4.22871 1.6
  name "cardboard box(1)"
  size 0.4 0.4 0.2
}
CardboardBox {
  translation -2.32383 4.22843 1.6
  name "cardboard box(2)"
  size 0.4 0.4 0.2
}
CardboardBox {
  translation -2.8933 4.22039 1.6
  name "cardboard box(3)"
  size 0.6 0.4 0.2
}
CardboardBox {
  translation -2.43254 4.24574 1.85
  name "cardboard box(5)"
  size 0.6 0.4 0.3
}
CardboardBox {
  translation -3.55672 4.21996 1.6
  name "cardboard box(4)"
  size 0.6 0.4 0.6
}
DEF flacon MedicineBottle {
  translation -2.28512 4.26301 0.32
  name "medicine bottle(22)"
}
DEF flacon MedicineBottle {
  translation -2.339 4.12935 0.32
  name "medicine bottle(23)"
}
DEF flacon MedicineBottle {
  translation -2.20029 4.28808 0.32
  name "medicine bottle(24)"
}
DEF flacon MedicineBottle {
  translation -2.10799 4.29355 0.32
  name "medicine bottle(25)"
}
DEF flacon MedicineBottle {
  translation -2.23479 4.10823 0.32
  name "medicine bottle(26)"
}
DEF flacon MedicineBottle {
  translation -2.13218 4.12491 0.32
  name "medicine bottle(27)"
}
DEF flacon MedicineBottle {
  translation -2.04445 4.20653 0.32
  name "medicine bottle(28)"
}
Cabinet {
  hidden position_6_0 6.406136652021645e-06
  hidden translation_7 -1.274821193743588e-06 -4.083317017844479e-12 0
  hidden rotation_7 0 0 1 6.406113008859535e-06
  hidden linearVelocity_7 -5.5511243454022806e-15 -2.7752555892101357e-15 -2.198364265335117e-15
  hidden angularVelocity_7 8.24819115044598e-18 -3.184671990672914e-17 1.3396712178599548e-18
  hidden position_10_0 -5.446180061596442e-06
  hidden translation_11 -9.212213574144841e-07 2.5085489241405412e-12 0
  hidden rotation_11 0 0 -1 5.446165469934237e-06
  hidden linearVelocity_11 2.7755566651195435e-15 -2.7755897623462698e-15 -2.3239850804971234e-15
  hidden angularVelocity_11 2.963244473986279e-18 5.860194724030475e-17 1.6819751613955854e-19
  hidden position_14_0 -1.224739196851478e-35
  hidden translation_15 -1.224739196851478e-35 0 0
  hidden linearVelocity_15 -4.4432558680513555e-35 4.357776724915333e-29 -1.720665652002837e-15
  hidden angularVelocity_15 3.289900035704163e-30 5.1335048304173884e-27 2.0659745066268927e-16
  hidden position_22_0 -1.2247391967354243e-35
  hidden translation_23 -1.2247391967354243e-35 0 0
  hidden linearVelocity_23 -4.4432558676075103e-35 4.357776724480027e-29 -7.374281365726444e-16
  hidden angularVelocity_23 3.289900035366422e-30 5.1335048373351225e-27 2.0659745066268927e-16
  hidden position_30_0 -1.224739196881233e-35
  hidden translation_31 -1.224739196881233e-35 0 0
  hidden linearVelocity_31 -4.443255868135719e-35 4.357776724998074e-29 -7.374281365726444e-16
  hidden angularVelocity_31 3.289900035765053e-30 5.133504831120067e-27 2.0659745066268927e-16
  hidden position_38_0 -2.548782146180773e-35
  hidden translation_39 -2.548782146180773e-35 0 0
  hidden linearVelocity_39 -1.1073860379496424e-34 1.0860821985004315e-28 -3.5434858510633582e-16
  hidden angularVelocity_39 3.288101559760908e-30 6.898165427330833e-27 2.0659745066268927e-16
  translation -2.03706 4.49032 2.47305e-14
  rotation 0 0 1 -1.5707953071795862
  name "cabinet(2)"
}
Cabinet {
  hidden position_6_0 6.4061366518057075e-06
  hidden translation_7 -1.2748211937006165e-06 -4.083317017844479e-12 0
  hidden rotation_7 0 0 1 6.406113008859535e-06
  hidden linearVelocity_7 -1.1459953186983597e-20 -2.775194921734881e-15 -2.1355538577541137e-15
  hidden angularVelocity_7 2.6608768181382917e-18 -3.180656608494493e-17 1.6087989004399482e-18
  hidden translation_11 -9.212213574145457e-07 2.5085489241405412e-12 0
  hidden rotation_11 0 0 -1 5.446165469934237e-06
  hidden linearVelocity_11 2.7755616858665733e-15 -2.7754465534026336e-15 -2.26117467291612e-15
  hidden angularVelocity_11 2.9632431991391694e-18 5.86019496399029e-17 -5.798330525502812e-19
  hidden position_14_0 -1.2247391968295307e-35
  hidden translation_15 -1.2247391968295307e-35 0 0
  hidden linearVelocity_15 -4.4432558679721054e-35 4.357776724837607e-29 -1.720665652002837e-15
  hidden angularVelocity_15 3.2899000356515984e-30 5.133504825037177e-27 2.0659745066268927e-16
  hidden position_22_0 -1.224739196942356e-35
  hidden translation_23 -1.224739196942356e-35 0 0
  hidden linearVelocity_23 -4.443255868356894e-35 4.3577767252149943e-29 -7.374281365726444e-16
  hidden angularVelocity_23 3.2899000359190215e-30 5.1335048416191336e-27 2.0659745066268927e-16
  hidden position_30_0 -1.2247391969885797e-35
  hidden translation_31 -1.2247391969885797e-35 0 0
  hidden linearVelocity_31 -4.4432558685248283e-35 4.3577767253796973e-29 -7.374281365726444e-16
  hidden angularVelocity_31 3.2899000360511254e-30 5.1335048338262525e-27 2.0659745066268927e-16
  hidden translation_39 -8.528313699689339e-08 0 0
  hidden linearVelocity_39 -5.0167839603406675e-15 -5.1151874994120216e-21 -3.5434858510633582e-16
  hidden angularVelocity_39 6.765488032756472e-29 1.419343496212521e-25 4.250880194632879e-15
  translation -3.63218 4.49573 3.20343e-14
  rotation 0 0 1 -1.5707953071795862
}
Cabinet {
  hidden position_6_0 6.406136652021823e-06
  hidden translation_7 -1.2748211937436233e-06 -4.083317017844479e-12 0
  hidden rotation_7 0 0 1 6.406113008859535e-06
  hidden linearVelocity_7 -5.55112577509686e-15 -2.775222249648013e-15 -2.198364265335117e-15
  hidden angularVelocity_7 -2.926432530599315e-18 -3.176641231163661e-17 1.4876481025072291e-18
  hidden translation_11 -9.212213574145457e-07 2.5085489241405412e-12 0
  hidden rotation_11 0 0 -1 5.446165469934237e-06
  hidden linearVelocity_11 2.7755640944599018e-15 -2.7753789573564726e-15 -2.26117467291612e-15
  hidden angularVelocity_11 2.963247835626547e-18 5.860196347730852e-17 -9.32430081615053e-19
  hidden position_14_0 -1.2247391971014068e-35
  hidden translation_15 -1.2247391971014068e-35 0 0
  hidden linearVelocity_15 -4.443255868959316e-35 4.357776725805826e-29 -1.720665652002837e-15
  hidden angularVelocity_15 3.289900036350944e-30 5.1335048560528654e-27 2.0659745066268927e-16
  hidden position_22_0 -1.2247391969794488e-35
  hidden translation_23 -1.2247391969794488e-35 0 0
  hidden linearVelocity_23 -4.443255868492301e-35 4.3577767253477954e-29 -7.374281365726444e-16
  hidden angularVelocity_23 3.289900036015236e-30 5.133504845011916e-27 2.0659745066268927e-16
  hidden position_30_0 -1.22473919696792e-35
  hidden translation_31 -1.22473919696792e-35 0 0
  hidden linearVelocity_31 -4.443255868450584e-35 4.357776725306882e-29 -7.374281365726444e-16
  hidden angularVelocity_31 3.2899000359883844e-30 5.1335048408401275e-27 2.0659745066268927e-16
  hidden position_38_0 -2.5487821457657425e-35
  hidden translation_39 -2.5487821457657425e-35 0 0
  hidden linearVelocity_39 -1.107386037768859e-34 1.086082198323126e-28 -3.5434858510633582e-16
  hidden angularVelocity_39 3.288101559226306e-30 6.898165425092192e-27 2.0659745066268927e-16
  translation -2.83745 4.49193 1.02783e-14
  rotation 0 0 1 -1.5707953071795862
  name "cabinet(1)"
}
DEF flacon MedicineBottle {
  translation 3.56926 4.39356 0.78
}
DEF flacon MedicineBottle {
  translation 3.69933 4.3255 0.78
  name "medicine bottle(6)"
}
DEF flacon MedicineBottle {
  translation 3.76588 4.32182 0.78
  name "medicine bottle(9)"
}
DEF flacon MedicineBottle {
  translation 3.9061 4.31311 0.78
  name "medicine bottle(10)"
}
DEF flacon MedicineBottle {
  translation 3.63443 4.3264 0.78
  name "medicine bottle(7)"
}
DEF flacon MedicineBottle {
  translation -2.87283 4.24044 0.32
  name "medicine bottle(12)"
}
DEF flacon MedicineBottle {
  translation -3.11988 4.12295 0.32
  name "medicine bottle(15)"
}
DEF flacon MedicineBottle {
  translation -3.91661 4.30275 0.32
  name "medicine bottle(16)"
}
DEF flacon MedicineBottle {
  translation -3.82355 4.33869 0.32
  name "medicine bottle(17)"
}
DEF flacon MedicineBottle {
  translation -3.91229 4.12358 0.32
  name "medicine bottle(18)"
}
DEF flacon MedicineBottle {
  translation -3.83771 4.17945 0.32
  name "medicine bottle(19)"
}
DEF flacon MedicineBottle {
  translation -3.74673 4.14264 0.32
  name "medicine bottle(20)"
}
DEF flacon MedicineBottle {
  translation -3.0661 4.22601 0.32
  name "medicine bottle(13)"
}
DEF flacon MedicineBottle {
  translation -2.96442 4.18594 0.32
  name "medicine bottle(14)"
}
DEF flacon MedicineBottle {
  translation -2.88014 4.09595 0.32
  name "medicine bottle(21)"
}
DEF flacon MedicineBottle {
  translation 3.84073 4.3196 0.78
  name "medicine bottle(8)"
}
DEF flacon MedicineBottle {
  translation 3.5709 4.32732 0.78
  name "medicine bottle(11)"
}
DEF flacon MedicineBottle {
  translation 3.63524 4.39233 0.78
  name "medicine bottle(1)"
}
DEF flacon MedicineBottle {
  translation 3.70087 4.39033 0.78
  name "medicine bottle(2)"
}
DEF flacon MedicineBottle {
  translation 3.76682 4.38993 0.78
  name "medicine bottle(3)"
}
DEF flacon MedicineBottle {
  translation 3.83551 4.38855 0.78
  name "medicine bottle(4)"
}
DEF flacon MedicineBottle {
  translation 3.89981 4.38844 0.78
  name "medicine bottle(5)"
}
HandSanitizer {
  translation -0.825129 1.05021 0.8
  rotation 0 0 1 0.785398
}
HandSanitizer {
  translation 0.579171 4.02396 0.81
  rotation 0 0 1 0.785398
  name "hand sanitizer(1)"
}
WallPlug {
  translation 1.19778 4.54094 0.84
  rotation 0 0 1 -1.5707953071795862
}
WallPlug {
  translation 1.27 4.54078 0.84
  rotation 0 0 1 -1.5707953071795862
  name "wall plug(1)"
}
WallPlug {
  translation 1.34 4.54078 0.84
  rotation 0 0 1 -1.5707953071795862
  name "wall plug(2)"
}
Desk {
  translation -0.68355 0.636776 -5.96647e-14
}
DoubleFluorescentLamp {
  translation 1.44444 0.650338 5
  rotation 0.7071067811862364 -0.7071067811862364 9.381857096790023e-07 3.14159
  name "double fuorescent lamp(17)"
}
DoubleFluorescentLamp {
  translation 1.4616 -1.34918 5
  rotation 0.7071067811862364 -0.7071067811862364 9.381857096790023e-07 3.14159
  name "double fuorescent lamp(13)"
}
OfficeChair {
  hidden position_0_0 -0.0014858155622627933
  hidden linearVelocity_0 -4.1793773079241215e-07 -2.300004829379485e-07 -3.312627787105972e-06
  hidden angularVelocity_0 1.6166059324342169e-06 -2.9375752761405195e-06 -2.9065551931995835e-11
  hidden translation_1 0 0 5.551115123125783e-17
  hidden rotation_1 0 0 -0.9999999999999999 0.001485815562318377
  hidden linearVelocity_1 -2.8244465819702833e-06 9.785287578451043e-07 -3.608355931153767e-06
  hidden angularVelocity_1 1.6477746968959972e-06 -2.919454882707153e-06 -2.5658778420604458e-05
  translation 1.0820208527082482 3.0703804819537908 -0.0014149133760749943
  rotation 0.0006797516671848518 -0.0026278718252802325 0.9999963161068849 0.5236008680716765
  name "office chair(2)"
}
Monitor {
  translation 2.00601 4.24785 0.75
  rotation 0 0 -1 1.8326
}
DesktopComputer {
  translation 1.02629 4.20872 0.75
  rotation 0 0 1 -1.5707953071795862
}
OfficeChair {
  hidden position_0_0 -0.0014858155622272662
  hidden linearVelocity_0 4.081541134942426e-07 -2.469461250377469e-07 -3.3126277871057673e-06
  hidden angularVelocity_0 1.7357236172382883e-06 2.8688023234846117e-06 -2.9065502890019857e-11
  hidden translation_1 0 0 5.551115123125783e-17
  hidden rotation_1 0 0 -1 0.001485815562318377
  hidden linearVelocity_1 5.64780486263744e-07 -2.9353091904012613e-06 -3.608355931571237e-06
  hidden angularVelocity_1 1.7044465883532178e-06 2.886735195416538e-06 -2.565877842259507e-05
  translation 2.2924491562637033 2.9694504974935714 -0.001414913376075022
  rotation 0.0007008719216573492 -0.00019433343663793982 0.9999997355064976 2.6179901583655014
}
OfficeChair {
  hidden position_0_0 -0.0014858155622432534
  hidden linearVelocity_0 -9.780959508020062e-09 -4.769449671834902e-07 -3.312627786992182e-06
  hidden angularVelocity_0 3.3523180177766654e-06 -6.87542720376468e-08 -2.906555397173061e-11
  hidden translation_1 0 0 5.551115123125783e-17
  hidden rotation_1 0 0 -1 0.001485815562318377
  hidden linearVelocity_1 -2.259647308011827e-06 -1.9567859088025753e-06 -3.6083559308128485e-06
  hidden angularVelocity_1 3.352209554284518e-06 -3.270113507825205e-08 -2.5658778419037833e-05
  translation 3.4174600089665184 3.0895209794439285 -0.0014149133760748556
  rotation 0.0006964090484678509 -0.0007085988808212652 0.9999995064509098 1.5708005196671335
  name "office chair(1)"
}
Table {
  translation 3.11466 3.98761 2.98877e-14
  rotation 0 0 1 1.5708
  name "table(1)"
}
OfficeTelephone {
  hidden linearVelocity_0 -1.6914019395768386e-07 -4.533342040546424e-07 -1.1206869441479891e-06
  hidden angularVelocity_0 5.5702384370741984e-06 -2.0784632903918985e-06 4.4664966759436344e-10
  translation 2.4404467706020703 4.1539777743499355 0.7431582736548078
  rotation 0.0007221170825754857 -0.0001368922065301148 -0.9999997299036849 1.570796358616844
}
Monitor {
  translation -0.745569 0.351457 0.71
  rotation 0 0 1 0.5236
  name "monitor ecografia"
}
Monitor {
  translation 1.53481 4.30841 0.75
  rotation 0 0 1 -1.5707953071795862
  name "monitor(2)"
}
Table {
  translation 1.32302 3.98419 3.01541e-14
  rotation 0 0 1 1.5708
}
ComputerMouse {
  hidden linearVelocity_0 -3.551393633214982e-18 6.073303263526481e-17 -9.272345241838535e-08
  hidden angularVelocity_0 -4.565150059692867e-15 6.258112885189725e-16 9.316039400610655e-17
  translation -0.6722354120757802 0.7136541373060874 0.7099607718657451
  rotation 4.918552455762095e-07 -1.8366025516247532e-06 0.9999999999981926 -2.6182589925174913
  name "computer ecografia mouse"
}
ComputerMouse {
  hidden linearVelocity_0 2.2703989719344328e-17 -1.984072402987731e-20 -9.272352336609107e-08
  hidden angularVelocity_0 -4.820678597377741e-16 -1.7227978102287063e-16 1.085590268439659e-16
  translation 1.8903 3.96342 0.7399607718658442
  rotation -2.3806401851379767e-06 -1.8366025520055888e-06 0.9999999999954797 1.314207117582323
  name "computer mouse(1)"
}
Keyboard {
  translation 1.54008 4.01052 0.75
  rotation 0 0 1 -1.5707953071795862
}
Keyboard {
  translation -0.526682 0.448736 0.71
  rotation 0 0 1 -2.6179953071795863
  name "keyboard ecografia"
}
Pedestrian {
  hidden translation_2 0.02973686231677275 5.551115123125783e-17 0.003932856814487934
  hidden rotation_2 0 -1 0 0.15781818181818244
  hidden translation_3 -0.02550812759288451 -5.551115123125783e-17 0.007416557289486925
  hidden rotation_3 0 -1 0 0.27054545454545215
  hidden translation_4 -0.05973190797681706 0 0.0008279017655310472
  hidden rotation_4 0 -1 0 0.16090909090908959
  hidden translation_5 -0.03046697284221507 -5.551115123125783e-17 0.000841064121527596
  hidden rotation_5 0 1 0 0.16036363636363413
  hidden translation_6 0.0033581465341919817 -5.551115123125783e-17 -0.0015688339491130854
  hidden rotation_6 0 1 0 0.03763636363635252
  hidden translation_7 0.0681448184948532 5.551115123125783e-17 -0.012947977995273308
  hidden rotation_7 0 1 0 0.18690909090909041
  hidden translation_8 0.22348380383232055 0 -0.15108295894004872
  hidden rotation_8 0 1 0 0.9238181818181825
  hidden translation_9 -0.7146697670986744 0 -0.42874887166826536
  hidden rotation_9 0 -0.9999999999999999 0 1.159636363636363
  hidden translation_10 -0.08893283508956137 2.7755575615628914e-17 0.0036229471045876593
  hidden rotation_10 0 -1 0 0.07618181818182117
  hidden translation_11 -0.06402018146990401 -2.7755575615628914e-17 0.0017002334804414043
  hidden rotation_11 0 -1 0 0.21199999999999597
  hidden translation_12 -0.1141847333928449 0 -0.004081399445961753
  hidden rotation_12 0 -1 0 0.1503636363636404
  hidden translation_13 -0.3626732934862562 0 -0.028151299339572056
  hidden rotation_13 0 -1 0 0.31254545454545557
  hidden translation_14 0.03873308658996428 0 0.0009818300747052588
  hidden rotation_14 0 -1 0 0.10472727272727045
  translation 1.1359999999999988 1.28 1.2579999999999993
  rotation 0 0 1 3.141592653589793
  name "doctor"
  controllerArgs [
    "--trajectory=\"0.92 1.28,1.78 1.28\" --speed=0.5 --pause_duration=3.0"
  ]
  shirtColor 0.291752 0.598627 0.655756
  pantsColor 0.219608 0.407965 0.525383
  shoesColor 0 0 0
  rightLegAngle -0.7719999999999974
  rightLowerLegAngle 0.6896363636363565
  rightFootAngle -0.31254545454545624
  leftLegAngle 0.37381818181818277
  leftLowerLegAngle 0.24036363636363708
  leftFootAngle -0.006181818181820453
  rightArmAngle 0.680363636363637
  rightLowerArmAngle -0.4323636363636345
  rightHandAngle 0.18690909090909139
  leftArmAngle -0.677818181818184
  leftLowerArmAngle -0.27054545454545237
  leftHandAngle -0.04090909090908945
  headAngle 0.0752727272727278
}
Robot {
  translation -0.03 -0.37 3.45
  children [
    Emitter {
      channel 1
    }
    SpotLight {
      attenuation 0 0 1
      beamWidth 0
      cutOffAngle 0.4
      direction 0 0 -2
      intensity 7
    }
    Camera {
      translation -8.87054e-07 -4.61711e-06 0.87
      rotation 0.7071072811853203 1.8797507474938104e-06 -0.7071062811849226 -3.1415853071795863
      children [
        RangeFinder {
          fieldOfView 0.8
          width 640
          height 480
          maxRange 15
        }
      ]
      fieldOfView 0.8
      width 640
      height 480
    }
    Solid {
      boundingObject Box {
        size 0.1 0.1 0.1
      }
    }
  ]
  name "camera"
  controller "camera"
}
Pose {
  translation 0.960002 -0.45 0.94
  rotation 0 0 1 1.5708
  children [
    CadShape {
      url [
        "../protos/meshes/patient_2.obj"
        "omino"
      ]
    }
  ]
}
Robot {
  translation -0.00661433 -1.24664 0.74
  children [
    Receiver {
      channel 1
    }
    SliderJoint {
      jointParameters JointParameters {
        position 0.8
        axis 1 0 0
        minStop -0.8
        maxStop 0.8
      }
      device [
        LinearMotor {
          name "slider_piston_base"
          maxVelocity 5
          minPosition -0.8
          maxPosition 0.8
        }
      ]
      endPoint Solid {
        translation 0.8 0 0
        children [
          Solid {
            translation 0 0.14 0.26
            children [
              Solid {
                children [
                  Solid {
                    children [
                      SliderJoint {
                        jointParameters JointParameters {
                          axis 0 1 0
                        }
                        device [
                          PositionSensor {
                            name "piston_motor_position"
                          }
                          LinearMotor {
                            name "piston_motor"
                          }
                        ]
                        endPoint Solid {
                          children [
                            HingeJoint {
                              jointParameters HingeJointParameters {
                                axis 0 1 0
                                anchor 0 0.099 0
                              }
                              device [
                                PositionSensor {
                                  name "position_rotational_motor_elbow"
                                }
                                RotationalMotor {
                                  name "rotational_motor_elbow"
                                }
                              ]
                              endPoint Solid {
                                translation 0 0.099 0
                                rotation 0 1 0 0
                                children [
                                  HingeJoint {
                                    jointParameters HingeJointParameters {
                                      axis 0 0 1
                                      anchor 0 0.162 0.099
                                    }
                                    device [
                                      PositionSensor {
                                      }
                                      RotationalMotor {
                                        name "rotational_motor_box"
                                      }
                                    ]
                                    endPoint Solid {
                                      translation 0 0.162 0.099
                                      children [
                                        HingeJoint {
                                          jointParameters HingeJointParameters {
                                            anchor 0.045 0 0.135
                                          }
                                          device [
                                            RotationalMotor {
                                              name "rotational_motor_arm"
                                            }
                                            PositionSensor {
                                              name "position_rotational_motor_arm"
                                            }
                                          ]
                                          endPoint Solid {
                                            translation 0.045 0 0.135
                                            rotation 1 0 0 0
                                            children [
                                              Solid {
                                                translation -0.0432 0.06 0
                                                children [
                                                  Solid {
                                                    translation -0.0432 0.33 0
                                                    rotation 0 0 1 3.141592653589793
                                                    children [
                                                      HingeJoint {
                                                        jointParameters HingeJointParameters {
                                                          anchor -0.045 0 0
                                                        }
                                                        device [
                                                          PositionSensor {
                                                            name "position_rotational_motor_double_gear"
                                                          }
                                                          RotationalMotor {
                                                            name "rotational_motor_double_gear"
                                                          }
                                                        ]
                                                        endPoint Solid {
                                                          rotation 1.2143019727953695e-17 -1.2143064331837653e-17 1 1.5708
                                                          children [
                                                            HingeJoint {
                                                              jointParameters HingeJointParameters {
                                                                axis 0 1 0
                                                                anchor 0 0.0432 0.216
                                                              }
                                                              device [
                                                                RotationalMotor {
                                                                  name "rotational_motor_upper_arm"
                                                                }
                                                                PositionSensor {
                                                                  name "position_rotational_motor_upper_arm"
                                                                }
                                                              ]
                                                              endPoint Solid {
                                                                translation 0 0.0864 0.216
                                                                rotation 8.732170000072219e-07 -3.2417399999695865e-06 0.9999999999943643 1.5707953071795862
                                                                children [
                                                                  Solid {
                                                                    translation -0.0434 0.065 0
                                                                    rotation 1 0 0 -1.5707953071795862
                                                                    children [
                                                                      Solid {
                                                                        translation 0.0432 0 0.3
                                                                        rotation -1 0 0 1.5708
                                                                        children [
                                                                          HingeJoint {
                                                                            jointParameters HingeJointParameters {
                                                                              anchor -0.0864 0 0
                                                                            }
                                                                            device [
                                                                              RotationalMotor {
                                                                                name "position_rotational_motor_probe"
                                                                              }
                                                                              PositionSensor {
                                                                                name "rotational_motor_probe"
                                                                              }
                                                                            ]
                                                                            endPoint Solid {
                                                                              translation -0.07 1.50494e-07 -3.39409e-07
                                                                              rotation 0.70710528118436 3.3905113482557537e-09 -0.707108281185553 3.14159
                                                                              children [
                                                                                HingeJoint {
                                                                                  jointParameters HingeJointParameters {
                                                                                    axis 0 0 1
                                                                                    anchor 0 0 0.05
                                                                                  }
                                                                                  endPoint Solid {
                                                                                    translation 0 0 0.04
                                                                                    children [
                                                                                      Shape {
                                                                                        appearance PBRAppearance {
                                                                                          metalness 0
                                                                                        }
                                                                                        geometry Mesh {
                                                                                          url [
                                                                                            "../protos/meshes/echoarm/probe.stl"
                                                                                          ]
                                                                                        }
                                                                                      }
                                                                                    ]
                                                                                  }
                                                                                }
                                                                                Shape {
                                                                                  appearance PBRAppearance {
                                                                                    baseColor 0 0.666667 1
                                                                                  }
                                                                                  geometry Mesh {
                                                                                    url [
                                                                                      "../protos/meshes/echoarm/probe_gear.stl"
                                                                                    ]
                                                                                  }
                                                                                }
                                                                              ]
                                                                              boundingObject Mesh {
                                                                                url [
                                                                                  "../protos/meshes/echoarm/probe_gear.stl"
                                                                                ]
                                                                              }
                                                                            }
                                                                          }
                                                                          Shape {
                                                                            appearance PBRAppearance {
                                                                              baseColor 0 0 0
                                                                            }
                                                                            geometry Mesh {
                                                                              url [
                                                                                "../protos/meshes/echoarm/probe_arm_gear.stl"
                                                                              ]
                                                                            }
                                                                          }
                                                                        ]
                                                                        boundingObject Mesh {
                                                                          url [
                                                                            "../protos/meshes/echoarm/probe_arm_gear.stl"
                                                                          ]
                                                                        }
                                                                      }
                                                                      Shape {
                                                                        appearance PBRAppearance {
                                                                          baseColor 0 0.666667 1
                                                                        }
                                                                        geometry Mesh {
                                                                          url [
                                                                            "../protos/meshes/echoarm/8upper_arm.stl"
                                                                          ]
                                                                        }
                                                                      }
                                                                    ]
                                                                    boundingObject Mesh {
                                                                      url [
                                                                        "../protos/meshes/echoarm/8upper_arm.stl"
                                                                      ]
                                                                    }
                                                                  }
                                                                  Shape {
                                                                    appearance PBRAppearance {
                                                                      baseColor 0 0 0
                                                                    }
                                                                    geometry Mesh {
                                                                      url [
                                                                        "../protos/meshes/echoarm/arm_gear.stl"
                                                                      ]
                                                                    }
                                                                  }
                                                                ]
                                                                boundingObject Mesh {
                                                                  url [
                                                                    "../protos/meshes/echoarm/arm_gear.stl"
                                                                  ]
                                                                }
                                                              }
                                                            }
                                                            Shape {
                                                              appearance PBRAppearance {
                                                                baseColor 0 0.666667 1
                                                              }
                                                              geometry Mesh {
                                                                url [
                                                                  "../protos/meshes/echoarm/7upper_arm_box.stl"
                                                                ]
                                                              }
                                                            }
                                                          ]
                                                          boundingObject Mesh {
                                                            url [
                                                              "../protos/meshes/echoarm/7upper_arm_box.stl"
                                                            ]
                                                          }
                                                        }
                                                      }
                                                      Shape {
                                                        appearance PBRAppearance {
                                                          baseColor 0 0 0
                                                        }
                                                        geometry Mesh {
                                                          url [
                                                            "../protos/meshes/echoarm/arm_gear.stl"
                                                          ]
                                                        }
                                                      }
                                                    ]
                                                    boundingObject Mesh {
                                                      url [
                                                        "../protos/meshes/echoarm/arm_gear.stl"
                                                      ]
                                                    }
                                                  }
                                                  Shape {
                                                    appearance PBRAppearance {
                                                      baseColor 0 0.666667 1
                                                      metalness 0.5
                                                    }
                                                    geometry Mesh {
                                                      url [
                                                        "../protos/meshes/echoarm/6lower_arm.stl"
                                                      ]
                                                    }
                                                  }
                                                ]
                                                boundingObject Mesh {
                                                  url [
                                                    "../protos/meshes/echoarm/6lower_arm.stl"
                                                  ]
                                                }
                                              }
                                              Shape {
                                                appearance PBRAppearance {
                                                  baseColor 0 0 0
                                                  metalness 0
                                                }
                                                geometry Mesh {
                                                  url [
                                                    "../protos/meshes/echoarm/arm_gear.stl"
                                                  ]
                                                }
                                              }
                                            ]
                                            boundingObject Mesh {
                                              url [
                                                "../protos/meshes/echoarm/arm_gear.stl"
                                              ]
                                            }
                                          }
                                        }
                                        Shape {
                                          appearance PBRAppearance {
                                            baseColor 0 0.666667 1
                                          }
                                          geometry Mesh {
                                            url [
                                              "../protos/meshes/echoarm/5elbow_box.stl"
                                            ]
                                          }
                                        }
                                      ]
                                      boundingObject Mesh {
                                        url [
                                          "../protos/meshes/echoarm/5elbow_box.stl"
                                        ]
                                      }
                                    }
                                  }
                                  Shape {
                                    appearance PBRAppearance {
                                      baseColor 0 0.666667 1
                                    }
                                    geometry Mesh {
                                      url [
                                        "../protos/meshes/echoarm/4elbow_base.stl"
                                      ]
                                    }
                                  }
                                ]
                                boundingObject Mesh {
                                  url [
                                    "../protos/meshes/echoarm/4elbow_base.stl"
                                  ]
                                }
                              }
                            }
                            Shape {
                              appearance PBRAppearance {
                                baseColor 0 0 0
                                metalness 0
                              }
                              geometry Mesh {
                                url [
                                  "../protos/meshes/echoarm/3piston_base.stl"
                                ]
                              }
                            }
                          ]
                          name "piston"
                          boundingObject Mesh {
                            url [
                              "../protos/meshes/echoarm/3piston_base.stl"
                            ]
                          }
                        }
                      }
                      Shape {
                        appearance PBRAppearance {
                          baseColor 0 0.666667 1
                        }
                        geometry Mesh {
                          url [
                            "../protos/meshes/echoarm/2base_box.stl"
                          ]
                        }
                      }
                    ]
                    boundingObject Mesh {
                      url [
                        "../protos/meshes/echoarm/2base_box.stl"
                      ]
                    }
                  }
                  Shape {
                    appearance PBRAppearance {
                      baseColor 0 0.666667 1
                    }
                    geometry Mesh {
                      url [
                        "../protos/meshes/echoarm/1base.stl"
                      ]
                    }
                  }
                ]
                name "base"
                boundingObject Mesh {
                  url [
                    "../protos/meshes/echoarm/1base.stl"
                  ]
                }
              }
            ]
          }
          Pose {
            translation 0 -0.07 0.01
            children [
              Shape {
                appearance PBRAppearance {
                  metalness 0
                }
                geometry Box {
                  size 0.3 0.05 0.7
                }
              }
            ]
          }
        ]
      }
    }
    Shape {
      appearance PBRAppearance {
      }
      geometry Box {
        size 1.9 0.15 0.05
      }
    }
  ]
  name "echoarm"
  controller "slider_test"
}
