#VRML_SIM R2025a utf8

EXTERNPROTO "https://raw.githubusercontent.com/cyberbotics/webots/R2025a/projects/objects/backgrounds/protos/TexturedBackground.proto"
EXTERNPROTO "https://raw.githubusercontent.com/cyberbotics/webots/R2025a/projects/objects/backgrounds/protos/TexturedBackgroundLight.proto"
EXTERNPROTO "https://raw.githubusercontent.com/cyberbotics/webots/R2025a/projects/objects/apartment_structure/protos/Ceiling.proto"
EXTERNPROTO "https://raw.githubusercontent.com/cyberbotics/webots/R2025a/projects/objects/hospital/protos/EmergencyExitSign.proto"
EXTERNPROTO "https://raw.githubusercontent.com/cyberbotics/webots/R2025a/projects/appearances/protos/PaintedWood.proto"
EXTERNPROTO "https://raw.githubusercontent.com/cyberbotics/webots/R2025a/projects/humans/pedestrian/protos/Pedestrian.proto"
EXTERNPROTO "https://raw.githubusercontent.com/cyberbotics/webots/R2025a/projects/objects/hospital/protos/Curtain.proto"
EXTERNPROTO "https://raw.githubusercontent.com/cyberbotics/webots/R2025a/projects/objects/tables/protos/Table.proto"
EXTERNPROTO "https://raw.githubusercontent.com/cyberbotics/webots/R2025a/projects/objects/chairs/protos/OfficeChair.proto"
EXTERNPROTO "https://raw.githubusercontent.com/cyberbotics/webots/R2025a/projects/objects/computers/protos/DesktopComputer.proto"
EXTERNPROTO "https://raw.githubusercontent.com/cyberbotics/webots/R2025a/projects/objects/computers/protos/Monitor.proto"
EXTERNPROTO "https://raw.githubusercontent.com/cyberbotics/webots/R2025a/projects/objects/computers/protos/Keyboard.proto"
EXTERNPROTO "https://raw.githubusercontent.com/cyberbotics/webots/R2025a/projects/objects/computers/protos/ComputerMouse.proto"
EXTERNPROTO "https://raw.githubusercontent.com/cyberbotics/webots/R2025a/projects/objects/telephone/protos/OfficeTelephone.proto"
EXTERNPROTO "https://raw.githubusercontent.com/cyberbotics/webots/R2025a/projects/appearances/protos/Roughcast.proto"
EXTERNPROTO "https://raw.githubusercontent.com/cyberbotics/webots/R2025a/projects/objects/apartment_structure/protos/Door.proto"
EXTERNPROTO "https://raw.githubusercontent.com/cyberbotics/webots/R2025a/projects/objects/tables/protos/Desk.proto"
EXTERNPROTO "https://raw.githubusercontent.com/cyberbotics/webots/R2025a/projects/objects/apartment_structure/protos/WallPlug.proto"
EXTERNPROTO "https://raw.githubusercontent.com/cyberbotics/webots/R2025a/projects/objects/hospital/protos/HandSanitizer.proto"
EXTERNPROTO "https://raw.githubusercontent.com/cyberbotics/webots/R2025a/projects/objects/hospital/protos/MedicineBottle.proto"
EXTERNPROTO "https://raw.githubusercontent.com/cyberbotics/webots/R2025a/projects/objects/cabinet/protos/Cabinet.proto"
EXTERNPROTO "https://raw.githubusercontent.com/cyberbotics/webots/R2025a/projects/objects/factory/containers/protos/CardboardBox.proto"
EXTERNPROTO "https://raw.githubusercontent.com/cyberbotics/webots/R2025a/projects/objects/school_furniture/protos/Clock.proto"
EXTERNPROTO "https://raw.githubusercontent.com/cyberbotics/webots/R2025a/projects/objects/school_furniture/protos/Book.proto"
EXTERNPROTO "https://raw.githubusercontent.com/cyberbotics/webots/R2025a/projects/objects/traffic/protos/Pole.proto"
EXTERNPROTO "https://raw.githubusercontent.com/cyberbotics/webots/R2025a/projects/objects/television/protos/Television.proto"
EXTERNPROTO "https://raw.githubusercontent.com/cyberbotics/webots/R2025a/projects/objects/paintings/protos/PortraitPainting.proto"
EXTERNPROTO "https://raw.githubusercontent.com/cyberbotics/webots/R2025a/projects/objects/apartment_structure/protos/Wall.proto"
EXTERNPROTO "https://raw.githubusercontent.com/cyberbotics/webots/R2025a/projects/objects/animals/protos/Cow.proto"
EXTERNPROTO "https://raw.githubusercontent.com/cyberbotics/webots/R2025a/projects/objects/floors/protos/Floor.proto"

WorldInfo {
  title "echoarm_simulation"
}
Viewpoint {
  orientation -0.33696966956013735 -0.08510590593057425 0.9376611469887554 3.606660989202466
  position 3.3109872420893627 1.4253752932207864 4.160230300224246
}
TexturedBackground {
}
TexturedBackgroundLight {
  texture "noon_cloudy_empty"
}
Ceiling {
  translation 0 0 5
  appearance Roughcast {
    colorOverride 0.413382 0.417441 0.417441
    textureTransform TextureTransform {
      scale 10 10
    }
  }
}
Floor {
  tileSize 2 1
  appearance PaintedWood {
  }
}
DEF Muro1 Solid {
  translation 0 -4.75 2.5
  children [
    Shape {
      appearance PaintedWood {
        colorOverride 0.74464 0.862104 1
      }
      geometry Box {
        size 10 0.5 5
      }
    }
  ]
  name "solid(2)"
  boundingObject Shape {
    appearance Appearance {
      material Material {
        ambientIntensity 0.7
        emissiveColor 0.7 0.7 0
      }
    }
    geometry Box {
      size 10 0.5 5
    }
  }
}
DEF Muro1 Solid {
  translation 0 4.75 2.5
  children [
    Shape {
      appearance PaintedWood {
        colorOverride 0.74464 0.862104 1
      }
      geometry Box {
        size 10 0.5 5
      }
    }
  ]
  boundingObject Shape {
    appearance Appearance {
      material Material {
        ambientIntensity 0.7
        emissiveColor 0.7 0.7 0
      }
    }
    geometry Box {
      size 10 0.5 5
    }
  }
}
Door {
  translation -0.821541 4.65491 1.31955e-13
  rotation 0 0 1 -1.5707953071795862
  position -0.002239663556469439
}
DEF Muro2 Solid {
  translation -5 0 2.5
  rotation -1.32199e-06 -1.33159e-06 1 1.57081
  children [
    Shape {
      appearance PaintedWood {
        colorOverride 0.74464 0.862104 1
      }
      geometry Box {
        size 10 0.5 5
      }
    }
  ]
  name "solid(1)"
  boundingObject Shape {
    appearance Appearance {
      material Material {
        ambientIntensity 0.7
        emissiveColor 0.7 0.7 0
      }
    }
    geometry Box {
      size 10 0.5 5
    }
  }
}
Curtain {
  translation -4.56 0.0849122 1.5
}
DEF Muro1 Solid {
  translation 4.76999 0.02 2.5
  rotation 0 0 1 1.5708
  children [
    Shape {
      appearance PaintedWood {
        colorOverride 0.74464 0.862104 1
      }
      geometry Box {
        size 10 0.5 5
      }
    }
  ]
  name "solid(3)"
  boundingObject Shape {
    appearance Appearance {
      material Material {
        ambientIntensity 0.7
        emissiveColor 0.7 0.7 0
      }
    }
    geometry Box {
      size 10 0.5 5
    }
  }
}
Curtain {
  translation -4.56156 1.51887 1.5
  name "curtain(2)"
}
Curtain {
  translation -4.57494 -2.79654 1.5
  name "curtain(3)"
}
Curtain {
  translation -4.54969 2.87899 1.5
  name "curtain(4)"
}
Curtain {
  translation -4.56596 -1.35865 1.5
  name "curtain(1)"
}
Solid {
  translation 0 0 -0.13
  children [
    Shape {
      appearance PBRAppearance {
        metalness 0
      }
      geometry Mesh {
        url [
          "../protos/meshes/lettino_piantana.stl"
        ]
      }
    }
  ]
  name "bed"
  boundingObject Shape {
    geometry Mesh {
      url [
        "../protos/meshes/lettino.stl"
      ]
    }
  }
}
EmergencyExitSign {
  translation -0.81 4.39 2.23
  rotation 1 0 0 1.5708
}
Cow {
  translation 2.6572 4.14 0.74
  rotation 0 0 1 -2.3561953071795863
  scale 0.1
}
Television {
  translation 1.28078 -1.0522 1.3
  rotation 0 0 -1 -0.523595307179586
  displayWidth 640
  displayHeight 480
  controller "tv"
}
Pole {
  translation 1.28997 -1.06903 -0.6000000029999799
}
Wall {
  translation -4.66 0.12 2.8
  size 0.1 7.5 0.05
}
Book {
  translation -2.3169277807918145 4.165556500733012 0.4892936498754481
  rotation 0.5777350417976991 -0.5766688957757095 0.5776462638361256 2.092410864310222
}
Book {
  translation -3.105050799899254 4.1792743071422755 0.4892936505415816
  rotation 0.5769495993738999 -0.5768393554913192 0.5782607696694079 2.0929278311658868
  name "book(2)"
}
Book {
  translation -2.3092490821128084 4.190119156431142 0.5086295911539933
  rotation 0.5781187445997823 -0.5761022853053644 0.5778277200068446 2.090853537833086
  name "book(3)"
}
Book {
  translation -3.118674413504542 4.200629202405788 0.5086386465046836
  rotation 0.576937301557942 -0.5761684478712292 0.5789415080547419 2.091076981597952
  name "book(6)"
}
Book {
  translation -2.3190743959954125 4.190177415157913 0.5281999528513575
  rotation 0.5787069696023066 -0.5757426168383482 0.5775973359442076 2.0898014139501027
  name "book(5)"
}
Book {
  translation -3.126041974689418 4.199985973622601 0.5478766327957353
  rotation 0.584105845511047 -0.5625994151373859 0.5850660298862824 2.10830668572348
  name "book(7)"
}
Book {
  translation -3.1053493955123597 4.214352675684482 0.5873542130041342
  rotation 0.6049476047099703 -0.5175368032776371 0.6051396969368593 2.177554976975951
  name "book(9)"
}
Book {
  translation -3.913559047626996 4.201461565594754 0.5285605740421834
  rotation 0.5738641576988296 -0.5814186788067017 0.5767427922768367 2.087789452594438
  name "book(10)"
}
Book {
  translation -2.2849428748564513 4.207226954068932 0.5476032120136222
  rotation 0.5793471037882997 -0.5752569376232588 0.5774395111597571 2.089527201302792
  name "book(11)"
}
Book {
  translation -2.2886605374677624 4.200812081914429 0.56740905899297
  rotation 0.5791765171535254 -0.5756502796920604 0.5772186045757401 2.0894466289973455
  name "book(12)"
}
Book {
  translation -3.1040153074392194 4.2310735087393025 0.5279899565589722
  rotation 0.57771866057556 -0.5749299398662429 0.5793934012984436 2.0913620026798796
  name "book(13)"
}
Book {
  translation -3.9111703152367197 4.2054498727462235 0.5682404509724445
  rotation 0.5876225674077177 -0.5531579948812247 0.5905217616414703 2.1304137356269366
  name "book(15)"
}
Book {
  translation -3.0638107295061703 4.25613332609103 0.5670298564506667
  rotation 0.5707263602507645 -0.5898435265858665 0.5712757966688794 2.0661128811220157
  name "book(16)"
}
Book {
  translation -2.296232690538416 4.180233363366484 0.5873896741052952
  rotation 0.5790664107956444 -0.575906377676486 0.5770735967273142 2.0892688080292823
  name "book(17)"
}
Book {
  translation -3.896318394658706 4.205012604018637 0.5483522145945566
  rotation 0.568396804727874 -0.592080980756892 0.5712838039023159 2.071894039252757
  name "book(14)"
}
Book {
  translation -3.8908501437981267 4.192420612891857 0.5089823629911369
  rotation 0.577804999483461 -0.5739571178159283 0.5802711516871665 2.098817015345248
  name "book(8)"
}
Book {
  translation -3.9258383470799445 4.187600305014257 0.36353337985485445
  rotation 0.32408040664195475 -0.4228217929634194 0.8462822350882621 2.0353285668600662
  name "book(4)"
}
Book {
  translation -3.886050790355331 4.180488728531921 0.48941138453475835
  rotation 0.5679208185682657 -0.5944061845556644 0.5693392939177205 2.069434138651862
  name "book(1)"
}
Clock {
  translation -0.780073 4.49139 2.77
  rotation 0 0 1 -1.5707953071795862
}
CardboardBox {
  translation -1.90445 4.22871 1.6
  name "cardboard box(1)"
  size 0.4 0.4 0.2
}
CardboardBox {
  translation -2.32383 4.22843 1.6
  name "cardboard box(2)"
  size 0.4 0.4 0.2
}
CardboardBox {
  translation -2.8933 4.22039 1.6
  name "cardboard box(3)"
  size 0.6 0.4 0.2
}
CardboardBox {
  translation -2.43254 4.24574 1.85
  name "cardboard box(5)"
  size 0.6 0.4 0.3
}
CardboardBox {
  translation -3.55672 4.21996 1.6
  name "cardboard box(4)"
  size 0.6 0.4 0.6
}
DEF flacon MedicineBottle {
  translation -2.28512 4.26301 0.32
  name "medicine bottle(22)"
}
DEF flacon MedicineBottle {
  translation -2.339 4.12935 0.32
  name "medicine bottle(23)"
}
DEF flacon MedicineBottle {
  translation -2.20029 4.28808 0.32
  name "medicine bottle(24)"
}
DEF flacon MedicineBottle {
  translation -2.10799 4.29355 0.32
  name "medicine bottle(25)"
}
DEF flacon MedicineBottle {
  translation -2.23479 4.10823 0.32
  name "medicine bottle(26)"
}
DEF flacon MedicineBottle {
  translation -2.13218 4.12491 0.32
  name "medicine bottle(27)"
}
DEF flacon MedicineBottle {
  translation -2.04445 4.20653 0.32
  name "medicine bottle(28)"
}
Cabinet {
  translation -2.03706 4.49032 2.47305e-14
  rotation 0 0 1 -1.5707953071795862
  name "cabinet(2)"
}
Cabinet {
  translation -3.63218 4.49573 3.20343e-14
  rotation 0 0 1 -1.5707953071795862
}
Cabinet {
  translation -2.83745 4.49193 1.02783e-14
  rotation 0 0 1 -1.5707953071795862
  name "cabinet(1)"
}
DEF flacon MedicineBottle {
  translation 3.56926 4.39356 0.78
}
DEF flacon MedicineBottle {
  translation 3.69933 4.3255 0.78
  name "medicine bottle(6)"
}
DEF flacon MedicineBottle {
  translation 3.76588 4.32182 0.78
  name "medicine bottle(9)"
}
DEF flacon MedicineBottle {
  translation 3.9061 4.31311 0.78
  name "medicine bottle(10)"
}
DEF flacon MedicineBottle {
  translation 3.63443 4.3264 0.78
  name "medicine bottle(7)"
}
DEF flacon MedicineBottle {
  translation -2.87283 4.24044 0.32
  name "medicine bottle(12)"
}
DEF flacon MedicineBottle {
  translation -3.11988 4.12295 0.32
  name "medicine bottle(15)"
}
DEF flacon MedicineBottle {
  translation -3.91661 4.30275 0.32
  name "medicine bottle(16)"
}
DEF flacon MedicineBottle {
  translation -3.82355 4.33869 0.32
  name "medicine bottle(17)"
}
DEF flacon MedicineBottle {
  translation -3.91229 4.12358 0.32
  name "medicine bottle(18)"
}
DEF flacon MedicineBottle {
  translation -3.83771 4.17945 0.32
  name "medicine bottle(19)"
}
DEF flacon MedicineBottle {
  translation -3.74673 4.14264 0.32
  name "medicine bottle(20)"
}
DEF flacon MedicineBottle {
  translation -3.0661 4.22601 0.32
  name "medicine bottle(13)"
}
DEF flacon MedicineBottle {
  translation -2.96442 4.18594 0.32
  name "medicine bottle(14)"
}
DEF flacon MedicineBottle {
  translation -2.88014 4.09595 0.32
  name "medicine bottle(21)"
}
DEF flacon MedicineBottle {
  translation 3.84073 4.3196 0.78
  name "medicine bottle(8)"
}
DEF flacon MedicineBottle {
  translation 3.5709 4.32732 0.78
  name "medicine bottle(11)"
}
DEF flacon MedicineBottle {
  translation 3.63524 4.39233 0.78
  name "medicine bottle(1)"
}
DEF flacon MedicineBottle {
  translation 3.70087 4.39033 0.78
  name "medicine bottle(2)"
}
DEF flacon MedicineBottle {
  translation 3.76682 4.38993 0.78
  name "medicine bottle(3)"
}
DEF flacon MedicineBottle {
  translation 3.83551 4.38855 0.78
  name "medicine bottle(4)"
}
DEF flacon MedicineBottle {
  translation 3.89981 4.38844 0.78
  name "medicine bottle(5)"
}
HandSanitizer {
  translation -0.825129 1.05021 0.8
  rotation 0 0 1 0.785398
}
HandSanitizer {
  translation 0.579171 4.02396 0.81
  rotation 0 0 1 0.785398
  name "hand sanitizer(1)"
}
WallPlug {
  translation 1.19778 4.54094 0.84
  rotation 0 0 1 -1.5707953071795862
}
WallPlug {
  translation 1.27 4.54078 0.84
  rotation 0 0 1 -1.5707953071795862
  name "wall plug(1)"
}
WallPlug {
  translation 1.34 4.54078 0.84
  rotation 0 0 1 -1.5707953071795862
  name "wall plug(2)"
}
Desk {
  translation -0.68355 0.636776 -5.96647e-14
}
OfficeChair {
  translation 1.082020861857568 3.0703804871125353 -0.0014153363769553728
  rotation 0.0006833805376253324 -0.002627724532666523 0.9999963140206175 0.523600869607158
  name "office chair(2)"
}
Monitor {
  translation 2.00601 4.24785 0.75
  rotation 0 0 -1 1.8326
}
DesktopComputer {
  translation 1.02629 4.20872 0.75
  rotation 0 0 1 -1.5707953071795862
}
OfficeChair {
  translation 2.2924491472214608 2.9694505028377787 -0.001415336376955345
  rotation 0.0007013239244534535 -0.00019347161852547253 0.9999997353567078 2.617990158932735
}
OfficeChair {
  translation 3.4174600090735354 3.089520989946846 -0.0014153363769552896
  rotation 0.0006975324004196496 -0.0007078880600821411 0.9999995061714005 1.570800520438982
  name "office chair(1)"
}
Table {
  translation 3.11466 3.98761 2.98877e-14
  rotation 0 0 1 1.5708
  name "table(1)"
}
OfficeTelephone {
  translation 2.4404467691482545 4.153977771272463 0.7431580818327023
  rotation 0.000722606571122665 -0.00013666849752493585 -0.9999997295806959 1.5707963621161116
}
Monitor {
  translation -0.745569 0.351457 0.71
  rotation 0 0 1 0.5236
  name "monitor ecografia"
}
Monitor {
  translation 1.53481 4.30841 0.75
  rotation 0 0 1 -1.5707953071795862
  name "monitor(2)"
}
Table {
  translation 1.32302 3.98419 3.01541e-14
  rotation 0 0 1 1.5708
}
ComputerMouse {
  translation -0.6722354120757802 0.7136541373060874 0.7099607600060497
  rotation 4.918552454479935e-07 -1.836602551493689e-06 0.9999999999981926 -2.6182589925174913
  name "computer ecografia mouse"
}
ComputerMouse {
  translation 1.8903 3.96342 0.7399607588114565
  rotation -2.380640185012694e-06 -1.8366025517251247e-06 0.9999999999954796 1.314207117582323
  name "computer mouse(1)"
}
Keyboard {
  translation 1.54008 4.01052 0.75
  rotation 0 0 1 -1.5707953071795862
}
Keyboard {
  translation -0.526682 0.448736 0.71
  rotation 0 0 1 -2.6179953071795863
  name "keyboard ecografia"
}
Pedestrian {
  translation 1.1359999999999988 1.28 1.2579999999999993
  rotation 0 0 1 3.141592653589793
  name "doctor"
  controllerArgs [
    "--trajectory=\"0.92 1.28,1.78 1.28\" --speed=0.5 --pause_duration=3.0"
  ]
  shirtColor 0.291752 0.598627 0.655756
  pantsColor 0.219608 0.407965 0.525383
  shoesColor 0 0 0
  rightLegAngle -0.7719999999999974
  rightLowerLegAngle 0.6896363636363565
  rightFootAngle -0.31254545454545624
  leftLegAngle 0.37381818181818277
  leftLowerLegAngle 0.24036363636363708
  leftFootAngle -0.006181818181820453
  rightArmAngle 0.680363636363637
  rightLowerArmAngle -0.4323636363636345
  rightHandAngle 0.18690909090909139
  leftArmAngle -0.677818181818184
  leftLowerArmAngle -0.27054545454545237
  leftHandAngle -0.04090909090908945
  headAngle 0.0752727272727278
}
DEF CAMERA Robot {
  translation -0.03 -0.37 3.45
  children [
    Emitter {
      channel 1
    }
    SpotLight {
      attenuation 0 0 1
      beamWidth 0
      cutOffAngle 0.5
      direction 0 0 -2
      intensity 7
    }
    DEF ZENIT_CAMERA Camera {
      translation -8.87054e-07 -4.61711e-06 0.87
      rotation 0.7071072811853203 1.8797507474938104e-06 -0.7071062811849226 -3.1415853071795863
      children [
        RangeFinder {
          fieldOfView 0.8
          width 640
          height 480
          maxRange 15
        }
      ]
      fieldOfView 0.8
      width 640
      height 480
    }
    Solid {
      boundingObject Box {
        size 0.1 0.1 0.1
      }
    }
  ]
  name "camera"
  controller "camera"
}
Pose {
  translation 0.95 -0.45 0.9
  rotation 0 0 1 1.5708
  children [
    CadShape {
      url [
        "../protos/meshes/patient_2.obj"
        "omino"
      ]
    }
  ]
}
DEF ECHOARM Robot {
  translation 0 -1.7 0.85
  children [
    Receiver {
      channel 1
    }
    DEF JOINT_SLIDER_BASE SliderJoint {
      jointParameters JointParameters {
        position 0.012
        axis 1 0 0
        minStop -0.8
        maxStop 0.8
      }
      device [
        PositionSensor {
          name "slider_base_sensor"
        }
        LinearMotor {
          name "slider_piston_base"
          maxVelocity 5
          minPosition -0.8
          maxPosition 0.8
        }
      ]
      endPoint DEF LINK_SLIDER_BASE Solid {
        translation 0.012 0 0
        children [
          Solid {
            translation 0 0.35 0.2
            children [
              DEF JOINT_PISTON SliderJoint {
                jointParameters JointParameters {
                  axis 0 1 0
                  maxStop 0.07
                }
                device [
                  PositionSensor {
                    name "piston_sensor"
                  }
                  LinearMotor {
                    name "piston_motor"
                  }
                ]
                endPoint DEF LINK_PISTON Solid {
                  translation 0 0.04 0
                  children [
                    DEF JOINT_ELBOW HingeJoint {
                      jointParameters HingeJointParameters {
                        axis 0 1 0
                        anchor 0 0.17 0
                      }
                      device [
                        RotationalMotor {
                          name "elbow_motor"
                        }
                        PositionSensor {
                          name "elbow_position"
                        }
                      ]
                      endPoint DEF LINK_ELBOW Solid {
                        translation 0 0.17 0
                        rotation 0 1 0 0
                        children [
                          DEF JOINT_LOWER_ARM_ROTATION HingeJoint {
                            jointParameters HingeJointParameters {
                              axis 0 0 1
                              anchor 0 0.075 0.0736
                            }
                            device [
                              RotationalMotor {
                                name "lower_arm_rotation_motor"
                              }
                              PositionSensor {
                                name "lower_arm_rotation_sensor"
                              }
                            ]
                            endPoint DEF LINK_LOWER_ARM_ROTATION Solid {
                              translation 0 0.075 0.0736
                              rotation 1 0 0 1.5708003061004252
                              children [
                                DEF JOINT_LOWER_ARM_VERTICAL HingeJoint {
                                  jointParameters HingeJointParameters {
                                    position 1.57
                                    anchor 0 0.06 0
                                  }
                                  device [
                                    PositionSensor {
                                      name "lower_arm_vertical_sensor"
                                    }
                                    RotationalMotor {
                                      name "lower_arm_vertical_motor"
                                    }
                                  ]
                                  endPoint DEF LINK_LOWER_ARM_VERTICAL Solid {
                                    translation 0.035 0.06 0
                                    rotation -0.0003952186568101267 0.0003981633558316492 0.9999998426340653 1.5707935371198234
                                    children [
                                      HingeJoint {
                                        jointParameters HingeJointParameters {
                                          position 1.57
                                          axis 0 1 0
                                          anchor 0.36 0.035 0
                                        }
                                        device [
                                          RotationalMotor {
                                            name "lower_upper_arm_rotation_motor"
                                          }
                                          PositionSensor {
                                            name "lower_upper_arm_rotation_sensor"
                                          }
                                        ]
                                        endPoint Solid {
                                          translation 0.36003981633553667 0.035 -0.04999998414659172
                                          rotation 0.5771976613402438 0.5771955411787425 0.5776574824121402 2.0939375257929127
                                          children [
                                            HingeJoint {
                                              jointParameters HingeJointParameters {
                                                axis 0 1 0
                                              }
                                              device [
                                                RotationalMotor {
                                                  name "upper_arm_rotation_motor"
                                                }
                                                PositionSensor {
                                                  name "upper_arm_rotation_sensor"
                                                }
                                              ]
                                              endPoint Solid {
                                                translation -2.06647e-15 0.01 0
                                                rotation 0 0 1 3.14159
                                                children [
                                                  HingeJoint {
                                                    jointParameters HingeJointParameters {
                                                      position -1.57
                                                      anchor 0 0.06 0
                                                    }
                                                    device [
                                                      RotationalMotor {
                                                        name "upper_arm_vertical_motor"
                                                      }
                                                      PositionSensor {
                                                        name "upper_arm_vertical_sensor"
                                                      }
                                                    ]
                                                    endPoint Solid {
                                                      translation 0.035 0.0599924491527619 0.009999997157739403
                                                      rotation -0.7071077321975892 -0.0002846055141529202 0.7071057728982869 3.141031773183817
                                                      children [
                                                        HingeJoint {
                                                          jointParameters HingeJointParameters {
                                                            axis 0 0 1
                                                            anchor 0.155 0 0.035
                                                          }
                                                          device [
                                                            RotationalMotor {
                                                              name "upper_arm_split_motor"
                                                            }
                                                          ]
                                                          endPoint Solid {
                                                            translation 0.155 0 0.010000000000000002
                                                            children [
                                                              HingeJoint {
                                                                jointParameters HingeJointParameters {
                                                                  axis 0 0 1
                                                                  anchor 0.155 0 0
                                                                }
                                                                device [
                                                                  RotationalMotor {
                                                                    name "probe_motor"
                                                                  }
                                                                ]
                                                                endPoint Solid {
                                                                  translation 0.13 0.008 -0.02
                                                                  rotation 0.5773489358556708 0.5773509358554485 -0.5773509358554485 2.0943999999999994
                                                                  children [
                                                                    Shape {
                                                                      appearance PBRAppearance {
                                                                        metalness 0
                                                                      }
                                                                      geometry Mesh {
                                                                        url [
                                                                          "../protos/meshes/echoarm/probe.stl"
                                                                        ]
                                                                      }
                                                                    }
                                                                  ]
                                                                  boundingObject Shape {
                                                                    appearance PBRAppearance {
                                                                      metalness 0
                                                                    }
                                                                    geometry Mesh {
                                                                      url [
                                                                        "../protos/meshes/echoarm/probe.stl"
                                                                      ]
                                                                    }
                                                                  }
                                                                }
                                                              }
                                                              Shape {
                                                                appearance PBRAppearance {
                                                                }
                                                                geometry Mesh {
                                                                  url [
                                                                    "../protos/meshes/echoarm/UpperArm_Component1.stl"
                                                                  ]
                                                                }
                                                              }
                                                            ]
                                                            boundingObject Mesh {
                                                              url [
                                                                "../protos/meshes/echoarm/UpperArm_Component1.stl"
                                                              ]
                                                            }
                                                          }
                                                        }
                                                        Shape {
                                                          appearance PBRAppearance {
                                                          }
                                                          geometry Mesh {
                                                            url [
                                                              "../protos/meshes/echoarm/UpperArm_Component2.stl"
                                                            ]
                                                          }
                                                        }
                                                      ]
                                                      boundingObject Mesh {
                                                        url [
                                                          "../protos/meshes/echoarm/UpperArm_Component2.stl"
                                                        ]
                                                      }
                                                    }
                                                  }
                                                  Shape {
                                                    appearance PBRAppearance {
                                                    }
                                                    geometry Mesh {
                                                      url [
                                                        "../protos/meshes/echoarm/UpperArmVertical.stl"
                                                      ]
                                                    }
                                                  }
                                                ]
                                                boundingObject Mesh {
                                                  url [
                                                    "../protos/meshes/echoarm/UpperArmVertical.stl"
                                                  ]
                                                }
                                              }
                                            }
                                            Shape {
                                              appearance PBRAppearance {
                                              }
                                              geometry Mesh {
                                                url [
                                                  "../protos/meshes/echoarm/UpperArmRotation.stl"
                                                ]
                                              }
                                            }
                                          ]
                                          boundingObject Mesh {
                                            url [
                                              "../protos/meshes/echoarm/UpperArmRotation.stl"
                                            ]
                                          }
                                        }
                                      }
                                      Shape {
                                        appearance PBRAppearance {
                                        }
                                        geometry Mesh {
                                          url [
                                            "../protos/meshes/echoarm/LowerArm.stl"
                                          ]
                                        }
                                      }
                                    ]
                                    boundingObject Mesh {
                                      url [
                                        "../protos/meshes/echoarm/LowerArm.stl"
                                      ]
                                    }
                                  }
                                }
                                Shape {
                                  appearance PBRAppearance {
                                  }
                                  geometry Mesh {
                                    url [
                                      "../protos/meshes/echoarm/LowerArmRotation.stl"
                                    ]
                                  }
                                }
                              ]
                              boundingObject Mesh {
                                url [
                                  "../protos/meshes/echoarm/LowerArmRotation.stl"
                                ]
                              }
                            }
                          }
                          Shape {
                            appearance PBRAppearance {
                            }
                            geometry Mesh {
                              url [
                                "../protos/meshes/echoarm/LowerElbow.stl"
                              ]
                            }
                          }
                        ]
                        boundingObject Mesh {
                          url [
                            "../protos/meshes/echoarm/LowerElbow.stl"
                          ]
                        }
                      }
                    }
                    Shape {
                      appearance PBRAppearance {
                      }
                      geometry Mesh {
                        url [
                          "../protos/meshes/echoarm/piston+elbow_box.stl"
                        ]
                      }
                    }
                  ]
                  name "LINK_PISTON"
                  boundingObject Mesh {
                    url [
                      "../protos/meshes/echoarm/piston+elbow_box.stl"
                    ]
                  }
                }
              }
              Shape {
                appearance PBRAppearance {
                }
                geometry Mesh {
                  url [
                    "../protos/meshes/echoarm/base+box.stl"
                  ]
                }
              }
            ]
            name "base_and_box"
            boundingObject Mesh {
              url [
                "../protos/meshes/echoarm/base+box.stl"
              ]
            }
          }
          Shape {
            appearance Appearance {
              material Material {
              }
              texture ImageTexture {
              }
            }
            geometry Box {
              size 0.4 0.15 0.8
            }
          }
        ]
      }
    }
    Shape {
      appearance PBRAppearance {
      }
      geometry Box {
        size 1.9 0.15 0.05
      }
    }
  ]
  name "echoarm"
  controller "ultrasound"
  supervisor TRUE
}
PortraitPainting {
  translation 1.07 4.47 2.275
  rotation 0 0 1 -1.5707953071795862
  textureUrl [
    "../textures/anatomy.jpg"
  ]
}
